Workbook
Name SelCounty: OFFSET('[1]County Populations'!$C$2,'[1]County Populations'!$M$6-1,0,'[1]County Populations'!$M$7-'[1]County Populations'!$M$6+1,1)
Name SelCounty: OFFSET('County Populations'!$C$2,'County Populations'!$M$6-1,0,'County Populations'!$M$7-'County Populations'!$M$6+1,1)
Name SelState: OFFSET('County Populations'!$G$2,'County Populations'!$M$3-1,0,'County Populations'!$M$4-'County Populations'!$M$3+1,1)

Sheet SummaryPage
C1: ="FEMA Region " & IFERROR(INDEX(State[Region],MATCH('Input Sheet'!$D$2,State[Code],0)),"") & " - "& IFERROR(INDEX(State[State],MATCH('Input Sheet'!$D$2,State[Code],0)),"Select State on Input Sheet") -> FEMA Region 5 - Michigan | O1: Print Area f(x): | P1: =OFFSET($A$1,0,0,MATCH("Grand Total",A:A,0),14) -> #VALUE!
C2: =" PRELIMINARY DAMAGE ASSESSMENT for " &'Input Sheet'!F1&" " & TEXT('Input Sheet'!H1,"M/D/YYYY") & " to " & TEXT('Input Sheet'!H2,"M/D/YYYY") -> PRELIMINARY DAMAGE ASSESSMENT for Flood 4/10/2026 to 4/21/2026 | O2: Max Row: | P2: =MATCH("Grand Total",A:A,0) -> 52
G3: Gross Total | I3: =SUM(Table1[A]) +SUM(Table1[B]) +SUM(Table1[C]) +SUM(Table1[D]) +SUM(Table1[E]) +SUM(Table1[F]) +SUM(Table1[G]) -> 24592237
G4: Less Counties < 50% PCI | I4: 1097723
G5: Validated Total | I5: =I3-I4 -> 23494514
C6: Cat A Debris | D6: Cat B Emergency | E6: Cat C Roads | F6: Cat D Water | G6: Cat E Buildings | H6: Cat F Utilities | I6: Cat G Other | J6: Total | K6: State Pop | L6: Cost per Capita | M6: Total Counties
A7: All Counties | B7: GRAND TOTAL: | C7: {=LOOKUP(2,1/(1-ISBLANK(C:C)),C:C)} -> 1238739.5 | D7: =LOOKUP(2,1/(1-ISBLANK(D:D)),D:D) -> 6593820.3 | E7: =LOOKUP(2,1/(1-ISBLANK(E:E)),E:E) -> 11634682 | F7: =LOOKUP(2,1/(1-ISBLANK(F:F)),F:F) -> 1278185.1 | G7: =LOOKUP(2,1/(1-ISBLANK(G:G)),G:G) -> 202713.38 | H7: =LOOKUP(2,1/(1-ISBLANK(H:H)),H:H) -> 792473.22 | I7: =LOOKUP(2,1/(1-ISBLANK(I:I)),I:I) -> 2851623 | J7: =LOOKUP(2,1/(1-ISBLANK(J:J)),J:J) -> 24592237 | K7: =VLOOKUP('Input Sheet'!$D$2 & " Grand Total",Pop[],4,FALSE) -> 10077331 | L7: =TEXT(J7/K7,"$0.00") &" " -> $2.44 | M7: =COUNTA(OFFSET($A$16,0,0,$P$2-10,1))-IFERROR(IF(VLOOKUP("State Agencies",A:A,1,FALSE)="State Agencies",1,0),0)-IFERROR(IF(VLOOKUP("(blank)",A:A,1,FALSE)="(blank)",1,0),0) -> 37
B8: PERCENTAGE: | C8: =C7/$J7 -> 0.050371159 | D8: =D7/$J7 -> 0.26812609 | E8: =E7/$J7 -> 0.47310386 | F8: =F7/$J7 -> 0.051975148 | G8: =G7/$J7 -> 0.0082429827 | H8: =H7/$J7 -> 0.032224528 | I8: =I7/$J7 -> 0.11595623 | J8: {="County Per Capita Min: " &TEXT(MIN(IF(ISNUMBER(OFFSET($L$15,0,0,$P$2-10,1)),OFFSET($L$15,0,0,$P$2-10,1))),"$0.00") & " | Max: " &TEXT(MAX(IF(ISNUMBER(OFFSET($L$15,0,0,$P$2-10,1)),OFFSET($L$15,0,0,$P$2-10,1))),"$0.00")} -> County Per Capita Min: $0.07 | Max: $330.85
A9: Counties that meet 50% threshold | B9: GRAND TOTAL: | C9: 0 | D9: 0 | E9: 44948 | F9: 0 | G9: 0 | H9: 0 | I9: 33625 | J9: =SUM(C9:I9) -> 78573
B10: PERCENTAGE: | C10: =C9/$J$9 -> 0 | D10: =D9/$J$9 -> 0 | E10: =E9/$J$9 -> 0.57205401 | F10: =F9/$J$9 -> 0 | G10: =G9/$J$9 -> 0 | H10: =H9/$J$9 -> 0 | I10: =I9/$J$9 -> 0.42794599
A11: Counties that meet 100% threshold | B11: GRAND TOTAL: | C11: =SUMPRODUCT(OFFSET(C$15,0,0,$P$2-10,1),OFFSET($P$15,0,0,$P$2-10,1)) -> 1072897.1 | D11: =SUMPRODUCT(OFFSET(D$15,0,0,$P$2-10,1),OFFSET($P$15,0,0,$P$2-10,1)) -> 6509052.4 | E11: =SUMPRODUCT(OFFSET(E$15,0,0,$P$2-10,1),OFFSET($P$15,0,0,$P$2-10,1)) -> 11161420 | F11: =SUMPRODUCT(OFFSET(F$15,0,0,$P$2-10,1),OFFSET($P$15,0,0,$P$2-10,1)) -> 1113981.7 | G11: =SUMPRODUCT(OFFSET(G$15,0,0,$P$2-10,1),OFFSET($P$15,0,0,$P$2-10,1)) -> 158956.38 | H11: =SUMPRODUCT(OFFSET(H$15,0,0,$P$2-10,1),OFFSET($P$15,0,0,$P$2-10,1)) -> 781898.22 | I11: =SUMPRODUCT(OFFSET(I$15,0,0,$P$2-10,1),OFFSET($P$15,0,0,$P$2-10,1)) -> 2617734.5 | J11: =SUMPRODUCT(OFFSET(J$15,0,0,$P$2-10,1),OFFSET($P$15,0,0,$P$2-10,1)) -> 23415940 | K11: =VLOOKUP('Input Sheet'!$D$2 & " Grand Total",Pop[],4,FALSE) -> 10077331 | L11: =TEXT(J11/K11,"$0.00") &" " -> $2.32 | M11: =COUNT(OFFSET($P$15,0,0,$P$2-10,1))-IFERROR(IF(VLOOKUP("State Agencies",A:A,1,FALSE)="State Agencies",1,0),0)-IFERROR(IF(VLOOKUP("(blank)",A:A,1,FALSE)="(blank)",1,0),0) -> 26
B12: PERCENTAGE: | C12: =C11/$J11 -> 0.045819093 | D12: =D11/$J11 -> 0.27797527 | E12: =E11/$J11 -> 0.47665905 | F12: =F11/$J11 -> 0.047573648 | G12: =G11/$J11 -> 0.0067883835 | H12: =H11/$J11 -> 0.033391707 | I12: =I11/$J11 -> 0.11179284 | J12: {="County Per Capita Min: " &TEXT(MIN(IF(ISNUMBER(OFFSET($Q$15,0,0,$P$2-10,1)),OFFSET($Q$15,0,0,$P$2-10,1))),"$0.00") & " | Max: " &TEXT(MAX(IF(ISNUMBER(OFFSET($Q$15,0,0,$P$2-10,1)),OFFSET($Q$15,0,0,$P$2-10,1))),"$0.00")} -> County Per Capita Min: $4.94 | Max: $330.85 | O12: CALCULATION FIELDS - DO NOT EDIT - SHOULD BE HIDDEN
A14: County | B14: Subrecipient | C14: Cat A | D14: Cat B | E14: Cat C | F14: Cat D | G14: Cat E | H14: Cat F | I14: Cat G | J14: Subtotal | K14: County Pop. | L14: Cost per Capita | M14: % of Eligible | N14: Applicants Pending | O14: Eligible County Total | P14: SUM PRODUCT INDICATOR | Q14: CPC Eligible | R14: Cty NS | S14: CTY | T14: STS
A15: Alcona | C15: 0 | D15: 79576.63 | E15: 370322.78 | F15: 0 | G15: 0 | H15: 0 | I15: 0 | J15: 449899.41 | K15: =IF($A15="","",VLOOKUP('Input Sheet'!$D$2 & " " & $A15,Pop[#All],4,FALSE)) -> 10167 | L15: =IFERROR(IF($A15="","",ROUND($J15/$K15,2)),"") -> 44.25 | M15: =IF(A15="Grand Total","",IF(ISNUMBER($O15),$O15*2/SUM($O:$O),"")) -> 0.019213382 | N15: =IF(OR($A15="",$A15="Grand Total"),IF($A15="Grand Total",SUM($N14:$N$15),""),SUMPRODUCT((Table1[County]=SummaryPage!$A15)*(Table1[Status]<>"Complete"))) -> 0 | O15: =IF($A15="Grand Total",SUM(INDIRECT(ADDRESS(1,COLUMN())&":"&ADDRESS(ROW()-1,COLUMN()))),IF(OR($A15="State Agencies",IFERROR(AND($L15>='Input Sheet'!$J$2,$A15<>""),0)),$J15,"")) -> 449899.41 | P15: =IF(OR($A15="",$A15="Grand Total"),"",IF(IFERROR(ROUND($J15/$K15,2),1000)>='Input Sheet'!$J$2,1,"")) -> 1 | Q15: =IFERROR($L15*$P15,"") -> 44.25 | R15: =IF(OR($A15="",$A15="Grand Total"),"",AND($J15=0,(SUMPRODUCT((Table1[County]=SummaryPage!$A15)*(Table1[Status]="Not Started"))+SUMPRODUCT((Table1[County]=SummaryPage!$A15)*(Table1[Status]="")))=SUMPRODUCT((Table1[County]=SummaryPage!$A15)*(Table1[Status]<>"Q")))) -> FALSE | S15: =IF(ISNUMBER($J15),IF(A15<>"",A15,IF(ISTEXT(S14),1,S14+1)),"") -> Alcona | T15: =IF(1=IF(ISNUMBER($J15),SUMPRODUCT((Table1[County]=OFFSET(S15,IF(ISNUMBER(S15),-S15,0),0))*(Table1[Subrecipient]=B15)*(Table1[Status]<>"Complete")),""),"Pending","")
A16: Allegan | C16: 104147.3 | D16: 0 | E16: 89967 | F16: 20282 | G16: 0 | H16: 0 | I16: 0 | J16: 214396.3 | K16: =IF($A16="","",VLOOKUP('Input Sheet'!$D$2 & " " & $A16,Pop[#All],4,FALSE)) -> 120502 | L16: =IFERROR(IF($A16="","",ROUND($J16/$K16,2)),"") -> 1.78 | M16: =IF(A16="Grand Total","",IF(ISNUMBER($O16),$O16*2/SUM($O:$O),"")) | N16: =IF(OR($A16="",$A16="Grand Total"),IF($A16="Grand Total",SUM($N$15:$N15),""),SUMPRODUCT((Table1[County]=SummaryPage!$A16)*(Table1[Status]<>"Complete"))) -> 0 | O16: =IF($A16="Grand Total",SUM(INDIRECT(ADDRESS(1,COLUMN())&":"&ADDRESS(ROW()-1,COLUMN()))),IF(OR($A16="State Agencies",IFERROR(AND($L16>='Input Sheet'!$J$2,$A16<>""),0)),$J16,"")) | P16: =IF(OR($A16="",$A16="Grand Total"),"",IF(IFERROR(ROUND($J16/$K16,2),1000)>='Input Sheet'!$J$2,1,"")) | Q16: =IFERROR($L16*$P16,"") | R16: =IF(OR($A16="",$A16="Grand Total"),"",AND($J16=0,(SUMPRODUCT((Table1[County]=SummaryPage!$A16)*(Table1[Status]="Not Started"))+SUMPRODUCT((Table1[County]=SummaryPage!$A16)*(Table1[Status]="")))=SUMPRODUCT((Table1[County]=SummaryPage!$A16)*(Table1[Status]<>"Q")))) -> FALSE
A17: Alpena | C17: 0 | D17: 0 | E17: 147388 | F17: 73375.93 | G17: 0 | H17: 0 | I17: 0 | J17: 220763.93 | K17: =IF($A17="","",VLOOKUP('Input Sheet'!$D$2 & " " & $A17,Pop[#All],4,FALSE)) -> 28907 | L17: =IFERROR(IF($A17="","",ROUND($J17/$K17,2)),"") -> 7.64 | M17: =IF(A17="Grand Total","",IF(ISNUMBER($O17),$O17*2/SUM($O:$O),"")) -> 0.0094279337 | N17: =IF(OR($A17="",$A17="Grand Total"),IF($A17="Grand Total",SUM($N$15:$N16),""),SUMPRODUCT((Table1[County]=SummaryPage!$A17)*(Table1[Status]<>"Complete"))) -> 0 | O17: =IF($A17="Grand Total",SUM(INDIRECT(ADDRESS(1,COLUMN())&":"&ADDRESS(ROW()-1,COLUMN()))),IF(OR($A17="State Agencies",IFERROR(AND($L17>='Input Sheet'!$J$2,$A17<>""),0)),$J17,"")) -> 220763.93 | P17: =IF(OR($A17="",$A17="Grand Total"),"",IF(IFERROR(ROUND($J17/$K17,2),1000)>='Input Sheet'!$J$2,1,"")) -> 1 | Q17: =IFERROR($L17*$P17,"") -> 7.64 | R17: =IF(OR($A17="",$A17="Grand Total"),"",AND($J17=0,(SUMPRODUCT((Table1[County]=SummaryPage!$A17)*(Table1[Status]="Not Started"))+SUMPRODUCT((Table1[County]=SummaryPage!$A17)*(Table1[Status]="")))=SUMPRODUCT((Table1[County]=SummaryPage!$A17)*(Table1[Status]<>"Q")))) -> FALSE
A18: Antrim | C18: 0 | D18: 28062.99 | E18: 0 | F18: 20183.44 | G18: 0 | H18: 0 | I18: 0 | J18: 48246.43 | K18: =IF($A18="","",VLOOKUP('Input Sheet'!$D$2 & " " & $A18,Pop[#All],4,FALSE)) -> 23431 | L18: =IFERROR(IF($A18="","",ROUND($J18/$K18,2)),"") -> 2.06 | M18: =IF(A18="Grand Total","",IF(ISNUMBER($O18),$O18*2/SUM($O:$O),"")) | N18: =IF(OR($A18="",$A18="Grand Total"),IF($A18="Grand Total",SUM($N$15:$N17),""),SUMPRODUCT((Table1[County]=SummaryPage!$A18)*(Table1[Status]<>"Complete"))) -> 0 | O18: =IF($A18="Grand Total",SUM(INDIRECT(ADDRESS(1,COLUMN())&":"&ADDRESS(ROW()-1,COLUMN()))),IF(OR($A18="State Agencies",IFERROR(AND($L18>='Input Sheet'!$J$2,$A18<>""),0)),$J18,"")) | P18: =IF(OR($A18="",$A18="Grand Total"),"",IF(IFERROR(ROUND($J18/$K18,2),1000)>='Input Sheet'!$J$2,1,"")) | Q18: =IFERROR($L18*$P18,"") | R18: =IF(OR($A18="",$A18="Grand Total"),"",AND($J18=0,(SUMPRODUCT((Table1[County]=SummaryPage!$A18)*(Table1[Status]="Not Started"))+SUMPRODUCT((Table1[County]=SummaryPage!$A18)*(Table1[Status]="")))=SUMPRODUCT((Table1[County]=SummaryPage!$A18)*(Table1[Status]<>"Q")))) -> FALSE
A19: Benzie | C19: 0 | D19: 0 | E19: 0 | F19: 35892.62 | G19: 0 | H19: 187982 | I19: 7812 | J19: 231686.62 | K19: =IF($A19="","",VLOOKUP('Input Sheet'!$D$2 & " " & $A19,Pop[#All],4,FALSE)) -> 17970 | L19: =IFERROR(IF($A19="","",ROUND($J19/$K19,2)),"") -> 12.89 | M19: =IF(A19="Grand Total","",IF(ISNUMBER($O19),$O19*2/SUM($O:$O),"")) -> 0.0098943976 | N19: =IF(OR($A19="",$A19="Grand Total"),IF($A19="Grand Total",SUM($N$15:$N18),""),SUMPRODUCT((Table1[County]=SummaryPage!$A19)*(Table1[Status]<>"Complete"))) -> 0 | O19: =IF($A19="Grand Total",SUM(INDIRECT(ADDRESS(1,COLUMN())&":"&ADDRESS(ROW()-1,COLUMN()))),IF(OR($A19="State Agencies",IFERROR(AND($L19>='Input Sheet'!$J$2,$A19<>""),0)),$J19,"")) -> 231686.62 | P19: =IF(OR($A19="",$A19="Grand Total"),"",IF(IFERROR(ROUND($J19/$K19,2),1000)>='Input Sheet'!$J$2,1,"")) -> 1 | Q19: =IFERROR($L19*$P19,"") -> 12.89 | R19: =IF(OR($A19="",$A19="Grand Total"),"",AND($J19=0,(SUMPRODUCT((Table1[County]=SummaryPage!$A19)*(Table1[Status]="Not Started"))+SUMPRODUCT((Table1[County]=SummaryPage!$A19)*(Table1[Status]="")))=SUMPRODUCT((Table1[County]=SummaryPage!$A19)*(Table1[Status]<>"Q")))) -> FALSE
A20: Charlevoix | C20: 0 | D20: 0 | E20: 190676.5 | F20: 26145 | G20: 0 | H20: 7936 | I20: 0 | J20: 224757.5 | K20: =IF($A20="","",VLOOKUP('Input Sheet'!$D$2 & " " & $A20,Pop[#All],4,FALSE)) -> 26054 | L20: =IFERROR(IF($A20="","",ROUND($J20/$K20,2)),"") -> 8.63 | M20: =IF(A20="Grand Total","",IF(ISNUMBER($O20),$O20*2/SUM($O:$O),"")) -> 0.0095984829 | N20: =IF(OR($A20="",$A20="Grand Total"),IF($A20="Grand Total",SUM($N$15:$N19),""),SUMPRODUCT((Table1[County]=SummaryPage!$A20)*(Table1[Status]<>"Complete"))) -> 0 | O20: =IF($A20="Grand Total",SUM(INDIRECT(ADDRESS(1,COLUMN())&":"&ADDRESS(ROW()-1,COLUMN()))),IF(OR($A20="State Agencies",IFERROR(AND($L20>='Input Sheet'!$J$2,$A20<>""),0)),$J20,"")) -> 224757.5 | P20: =IF(OR($A20="",$A20="Grand Total"),"",IF(IFERROR(ROUND($J20/$K20,2),1000)>='Input Sheet'!$J$2,1,"")) -> 1 | Q20: =IFERROR($L20*$P20,"") -> 8.63 | R20: =IF(OR($A20="",$A20="Grand Total"),"",AND($J20=0,(SUMPRODUCT((Table1[County]=SummaryPage!$A20)*(Table1[Status]="Not Started"))+SUMPRODUCT((Table1[County]=SummaryPage!$A20)*(Table1[Status]="")))=SUMPRODUCT((Table1[County]=SummaryPage!$A20)*(Table1[Status]<>"Q")))) -> FALSE
A21: Cheboygan | C21: 820369.85 | D21: 5255688.6 | E21: 905964 | F21: 624844.77 | G21: 0 | H21: 66138 | I21: 789903 | J21: 8462908.2 | K21: =IF($A21="","",VLOOKUP('Input Sheet'!$D$2 & " " & $A21,Pop[#All],4,FALSE)) -> 25579 | L21: =IFERROR(IF($A21="","",ROUND($J21/$K21,2)),"") -> 330.85 | M21: =IF(A21="Grand Total","",IF(ISNUMBER($O21),$O21*2/SUM($O:$O),"")) -> 0.36141655 | N21: =IF(OR($A21="",$A21="Grand Total"),IF($A21="Grand Total",SUM($N$15:$N20),""),SUMPRODUCT((Table1[County]=SummaryPage!$A21)*(Table1[Status]<>"Complete"))) -> 0 | O21: =IF($A21="Grand Total",SUM(INDIRECT(ADDRESS(1,COLUMN())&":"&ADDRESS(ROW()-1,COLUMN()))),IF(OR($A21="State Agencies",IFERROR(AND($L21>='Input Sheet'!$J$2,$A21<>""),0)),$J21,"")) -> 8462908.2 | P21: =IF(OR($A21="",$A21="Grand Total"),"",IF(IFERROR(ROUND($J21/$K21,2),1000)>='Input Sheet'!$J$2,1,"")) -> 1 | Q21: =IFERROR($L21*$P21,"") -> 330.85 | R21: =IF(OR($A21="",$A21="Grand Total"),"",AND($J21=0,(SUMPRODUCT((Table1[County]=SummaryPage!$A21)*(Table1[Status]="Not Started"))+SUMPRODUCT((Table1[County]=SummaryPage!$A21)*(Table1[Status]="")))=SUMPRODUCT((Table1[County]=SummaryPage!$A21)*(Table1[Status]<>"Q")))) -> FALSE
A22: Clare | C22: 0 | D22: 0 | E22: 38906.37 | F22: 0 | G22: 0 | H22: 4075 | I22: 0 | J22: 42981.37 | K22: =IF($A22="","",VLOOKUP('Input Sheet'!$D$2 & " " & $A22,Pop[#All],4,FALSE)) -> 30856 | L22: =IFERROR(IF($A22="","",ROUND($J22/$K22,2)),"") -> 1.39 | M22: =IF(A22="Grand Total","",IF(ISNUMBER($O22),$O22*2/SUM($O:$O),"")) | N22: =IF(OR($A22="",$A22="Grand Total"),IF($A22="Grand Total",SUM($N$15:$N21),""),SUMPRODUCT((Table1[County]=SummaryPage!$A22)*(Table1[Status]<>"Complete"))) -> 0 | O22: =IF($A22="Grand Total",SUM(INDIRECT(ADDRESS(1,COLUMN())&":"&ADDRESS(ROW()-1,COLUMN()))),IF(OR($A22="State Agencies",IFERROR(AND($L22>='Input Sheet'!$J$2,$A22<>""),0)),$J22,"")) | P22: =IF(OR($A22="",$A22="Grand Total"),"",IF(IFERROR(ROUND($J22/$K22,2),1000)>='Input Sheet'!$J$2,1,"")) | Q22: =IFERROR($L22*$P22,"") | R22: =IF(OR($A22="",$A22="Grand Total"),"",AND($J22=0,(SUMPRODUCT((Table1[County]=SummaryPage!$A22)*(Table1[Status]="Not Started"))+SUMPRODUCT((Table1[County]=SummaryPage!$A22)*(Table1[Status]="")))=SUMPRODUCT((Table1[County]=SummaryPage!$A22)*(Table1[Status]<>"Q")))) -> FALSE
A23: Crawford | C23: 0 | D23: 17423 | E23: 49288 | F23: 0 | G23: 0 | H23: 0 | I23: 804 | J23: 67515 | K23: =IF($A23="","",VLOOKUP('Input Sheet'!$D$2 & " " & $A23,Pop[#All],4,FALSE)) -> 12988 | L23: =IFERROR(IF($A23="","",ROUND($J23/$K23,2)),"") -> 5.2 | M23: =IF(A23="Grand Total","",IF(ISNUMBER($O23),$O23*2/SUM($O:$O),"")) -> 0.0028832923 | N23: =IF(OR($A23="",$A23="Grand Total"),IF($A23="Grand Total",SUM($N$15:$N22),""),SUMPRODUCT((Table1[County]=SummaryPage!$A23)*(Table1[Status]<>"Complete"))) -> 0 | O23: =IF($A23="Grand Total",SUM(INDIRECT(ADDRESS(1,COLUMN())&":"&ADDRESS(ROW()-1,COLUMN()))),IF(OR($A23="State Agencies",IFERROR(AND($L23>='Input Sheet'!$J$2,$A23<>""),0)),$J23,"")) -> 67515 | P23: =IF(OR($A23="",$A23="Grand Total"),"",IF(IFERROR(ROUND($J23/$K23,2),1000)>='Input Sheet'!$J$2,1,"")) -> 1 | Q23: =IFERROR($L23*$P23,"") -> 5.2 | R23: =IF(OR($A23="",$A23="Grand Total"),"",AND($J23=0,(SUMPRODUCT((Table1[County]=SummaryPage!$A23)*(Table1[Status]="Not Started"))+SUMPRODUCT((Table1[County]=SummaryPage!$A23)*(Table1[Status]="")))=SUMPRODUCT((Table1[County]=SummaryPage!$A23)*(Table1[Status]<>"Q")))) -> FALSE
A24: Eaton | C24: 0 | D24: 196291.04 | E24: 503921.9 | F24: 124264.1 | G24: 0 | H24: 0 | I24: 0 | J24: 824477.04 | K24: =IF($A24="","",VLOOKUP('Input Sheet'!$D$2 & " " & $A24,Pop[#All],4,FALSE)) -> 109175 | L24: =IFERROR(IF($A24="","",ROUND($J24/$K24,2)),"") -> 7.55 | M24: =IF(A24="Grand Total","",IF(ISNUMBER($O24),$O24*2/SUM($O:$O),"")) -> 0.035210077 | N24: =IF(OR($A24="",$A24="Grand Total"),IF($A24="Grand Total",SUM($N$15:$N23),""),SUMPRODUCT((Table1[County]=SummaryPage!$A24)*(Table1[Status]<>"Complete"))) -> 0 | O24: =IF($A24="Grand Total",SUM(INDIRECT(ADDRESS(1,COLUMN())&":"&ADDRESS(ROW()-1,COLUMN()))),IF(OR($A24="State Agencies",IFERROR(AND($L24>='Input Sheet'!$J$2,$A24<>""),0)),$J24,"")) -> 824477.04 | P24: =IF(OR($A24="",$A24="Grand Total"),"",IF(IFERROR(ROUND($J24/$K24,2),1000)>='Input Sheet'!$J$2,1,"")) -> 1 | Q24: =IFERROR($L24*$P24,"") -> 7.55 | R24: =IF(OR($A24="",$A24="Grand Total"),"",AND($J24=0,(SUMPRODUCT((Table1[County]=SummaryPage!$A24)*(Table1[Status]="Not Started"))+SUMPRODUCT((Table1[County]=SummaryPage!$A24)*(Table1[Status]="")))=SUMPRODUCT((Table1[County]=SummaryPage!$A24)*(Table1[Status]<>"Q")))) -> FALSE
A25: Emmet | C25: 0 | D25: 191373.9 | E25: 0 | F25: 0 | G25: 6000 | H25: 0 | I25: 80643.76 | J25: 278017.66 | K25: =IF($A25="","",VLOOKUP('Input Sheet'!$D$2 & " " & $A25,Pop[#All],4,FALSE)) -> 34112 | L25: =IFERROR(IF($A25="","",ROUND($J25/$K25,2)),"") -> 8.15 | M25: =IF(A25="Grand Total","",IF(ISNUMBER($O25),$O25*2/SUM($O:$O),"")) -> 0.011873009 | N25: =IF(OR($A25="",$A25="Grand Total"),IF($A25="Grand Total",SUM($N$15:$N24),""),SUMPRODUCT((Table1[County]=SummaryPage!$A25)*(Table1[Status]<>"Complete"))) -> 0 | O25: =IF($A25="Grand Total",SUM(INDIRECT(ADDRESS(1,COLUMN())&":"&ADDRESS(ROW()-1,COLUMN()))),IF(OR($A25="State Agencies",IFERROR(AND($L25>='Input Sheet'!$J$2,$A25<>""),0)),$J25,"")) -> 278017.66 | P25: =IF(OR($A25="",$A25="Grand Total"),"",IF(IFERROR(ROUND($J25/$K25,2),1000)>='Input Sheet'!$J$2,1,"")) -> 1 | Q25: =IFERROR($L25*$P25,"") -> 8.15 | R25: =IF(OR($A25="",$A25="Grand Total"),"",AND($J25=0,(SUMPRODUCT((Table1[County]=SummaryPage!$A25)*(Table1[Status]="Not Started"))+SUMPRODUCT((Table1[County]=SummaryPage!$A25)*(Table1[Status]="")))=SUMPRODUCT((Table1[County]=SummaryPage!$A25)*(Table1[Status]<>"Q")))) -> FALSE
A26: Grand Traverse | C26: 198000 | D26: 143429.52 | E26: 1693083.5 | F26: 0 | G26: 73925.12 | H26: 0 | I26: 581892.84 | J26: 2690331 | K26: =IF($A26="","",VLOOKUP('Input Sheet'!$D$2 & " " & $A26,Pop[#All],4,FALSE)) -> 95238 | L26: =IFERROR(IF($A26="","",ROUND($J26/$K26,2)),"") -> 28.25 | M26: =IF(A26="Grand Total","",IF(ISNUMBER($O26),$O26*2/SUM($O:$O),"")) -> 0.11489315 | N26: =IF(OR($A26="",$A26="Grand Total"),IF($A26="Grand Total",SUM($N$15:$N25),""),SUMPRODUCT((Table1[County]=SummaryPage!$A26)*(Table1[Status]<>"Complete"))) -> 0 | O26: =IF($A26="Grand Total",SUM(INDIRECT(ADDRESS(1,COLUMN())&":"&ADDRESS(ROW()-1,COLUMN()))),IF(OR($A26="State Agencies",IFERROR(AND($L26>='Input Sheet'!$J$2,$A26<>""),0)),$J26,"")) -> 2690331 | P26: =IF(OR($A26="",$A26="Grand Total"),"",IF(IFERROR(ROUND($J26/$K26,2),1000)>='Input Sheet'!$J$2,1,"")) -> 1 | Q26: =IFERROR($L26*$P26,"") -> 28.25 | R26: =IF(OR($A26="",$A26="Grand Total"),"",AND($J26=0,(SUMPRODUCT((Table1[County]=SummaryPage!$A26)*(Table1[Status]="Not Started"))+SUMPRODUCT((Table1[County]=SummaryPage!$A26)*(Table1[Status]="")))=SUMPRODUCT((Table1[County]=SummaryPage!$A26)*(Table1[Status]<>"Q")))) -> FALSE
A27: Gratiot | C27: 12087.22 | D27: 19284.33 | E27: 60310 | F27: 95900 | G27: 8591.26 | H27: 10008.1 | I27: 0 | J27: 206180.91 | K27: =IF($A27="","",VLOOKUP('Input Sheet'!$D$2 & " " & $A27,Pop[#All],4,FALSE)) -> 41761 | L27: =IFERROR(IF($A27="","",ROUND($J27/$K27,2)),"") -> 4.94 | M27: =IF(A27="Grand Total","",IF(ISNUMBER($O27),$O27*2/SUM($O:$O),"")) -> 0.0088051519 | N27: =IF(OR($A27="",$A27="Grand Total"),IF($A27="Grand Total",SUM($N$15:$N26),""),SUMPRODUCT((Table1[County]=SummaryPage!$A27)*(Table1[Status]<>"Complete"))) -> 0 | O27: =IF($A27="Grand Total",SUM(INDIRECT(ADDRESS(1,COLUMN())&":"&ADDRESS(ROW()-1,COLUMN()))),IF(OR($A27="State Agencies",IFERROR(AND($L27>='Input Sheet'!$J$2,$A27<>""),0)),$J27,"")) -> 206180.91 | P27: =IF(OR($A27="",$A27="Grand Total"),"",IF(IFERROR(ROUND($J27/$K27,2),1000)>='Input Sheet'!$J$2,1,"")) -> 1 | Q27: =IFERROR($L27*$P27,"") -> 4.94 | R27: =IF(OR($A27="",$A27="Grand Total"),"",AND($J27=0,(SUMPRODUCT((Table1[County]=SummaryPage!$A27)*(Table1[Status]="Not Started"))+SUMPRODUCT((Table1[County]=SummaryPage!$A27)*(Table1[Status]="")))=SUMPRODUCT((Table1[County]=SummaryPage!$A27)*(Table1[Status]<>"Q")))) -> FALSE
... A52: Grand Total | C52: 1238739.5 | D52: 6593820.3 | E52: 11634682 | F52: 1278185.1 | G52: 202713.38 | H52: 792473.22 | I52: 2851623 | J52: 24592237 | K52: =IF($A52="","",VLOOKUP('Input Sheet'!$D$2 & " " & $A52,Pop[#All],4,FALSE)) -> 10077331 | L52: =IFERROR(IF($A52="","",ROUND($J52/$K52,2)),"") -> 2.44 | M52: =IF(A52="Grand Total","",IF(ISNUMBER($O52),$O52*2/SUM($O:$O),"")) | N52: =IF(OR($A52="",$A52="Grand Total"),IF($A52="Grand Total",SUM($N$15:$N51),""),SUMPRODUCT((Table1[County]=SummaryPage!$A52)*(Table1[Status]<>"Complete"))) -> 0 | O52: =IF($A52="Grand Total",SUM(INDIRECT(ADDRESS(1,COLUMN())&":"&ADDRESS(ROW()-1,COLUMN()))),IF(OR($A52="State Agencies",IFERROR(AND($L52>='Input Sheet'!$J$2,$A52<>""),0)),$J52,"")) -> 23415940 | P52: =IF(OR($A52="",$A52="Grand Total"),"",IF(IFERROR(ROUND($J52/$K52,2),1000)>='Input Sheet'!$J$2,1,"")) | Q52: =IFERROR($L52*$P52,"") | R52: =IF(OR($A52="",$A52="Grand Total"),"",AND($J52=0,(SUMPRODUCT((Table1[County]=SummaryPage!$A52)*(Table1[Status]="Not Started"))+SUMPRODUCT((Table1[County]=SummaryPage!$A52)*(Table1[Status]="")))=SUMPRODUCT((Table1[County]=SummaryPage!$A52)*(Table1[Status]<>"Q"))))
K53: =IF($A53="","",VLOOKUP('Input Sheet'!$D$2 & " " & $A53,Pop[#All],4,FALSE)) | L53: =IFERROR(IF($A53="","",ROUND($J53/$K53,2)),"") | M53: =IF(A53="Grand Total","",IF(ISNUMBER($O53),$O53*2/SUM($O:$O),"")) | N53: =IF(OR($A53="",$A53="Grand Total"),IF($A53="Grand Total",SUM($N$15:$N52),""),SUMPRODUCT((Table1[County]=SummaryPage!$A53)*(Table1[Status]<>"Complete"))) | O53: =IF($A53="Grand Total",SUM(INDIRECT(ADDRESS(1,COLUMN())&":"&ADDRESS(ROW()-1,COLUMN()))),IF(OR($A53="State Agencies",IFERROR(AND($L53>='Input Sheet'!$J$2,$A53<>""),0)),$J53,"")) | P53: =IF(OR($A53="",$A53="Grand Total"),"",IF(IFERROR(ROUND($J53/$K53,2),1000)>='Input Sheet'!$J$2,1,"")) | Q53: =IFERROR($L53*$P53,"") | R53: =IF(OR($A53="",$A53="Grand Total"),"",AND($J53=0,(SUMPRODUCT((Table1[County]=SummaryPage!$A53)*(Table1[Status]="Not Started"))+SUMPRODUCT((Table1[County]=SummaryPage!$A53)*(Table1[Status]="")))=SUMPRODUCT((Table1[County]=SummaryPage!$A53)*(Table1[Status]<>"Q"))))
K54: =IF($A54="","",VLOOKUP('Input Sheet'!$D$2 & " " & $A54,Pop[#All],4,FALSE)) | L54: =IFERROR(IF($A54="","",ROUND($J54/$K54,2)),"") | M54: =IF(A54="Grand Total","",IF(ISNUMBER($O54),$O54*2/SUM($O:$O),"")) | N54: =IF(OR($A54="",$A54="Grand Total"),IF($A54="Grand Total",SUM($N$15:$N53),""),SUMPRODUCT((Table1[County]=SummaryPage!$A54)*(Table1[Status]<>"Complete"))) | O54: =IF($A54="Grand Total",SUM(INDIRECT(ADDRESS(1,COLUMN())&":"&ADDRESS(ROW()-1,COLUMN()))),IF(OR($A54="State Agencies",IFERROR(AND($L54>='Input Sheet'!$J$2,$A54<>""),0)),$J54,"")) | P54: =IF(OR($A54="",$A54="Grand Total"),"",IF(IFERROR(ROUND($J54/$K54,2),1000)>='Input Sheet'!$J$2,1,"")) | Q54: =IFERROR($L54*$P54,"") | R54: =IF(OR($A54="",$A54="Grand Total"),"",AND($J54=0,(SUMPRODUCT((Table1[County]=SummaryPage!$A54)*(Table1[Status]="Not Started"))+SUMPRODUCT((Table1[County]=SummaryPage!$A54)*(Table1[Status]="")))=SUMPRODUCT((Table1[County]=SummaryPage!$A54)*(Table1[Status]<>"Q"))))
K55: =IF($A55="","",VLOOKUP('Input Sheet'!$D$2 & " " & $A55,Pop[#All],4,FALSE)) | L55: =IFERROR(IF($A55="","",ROUND($J55/$K55,2)),"") | M55: =IF(A55="Grand Total","",IF(ISNUMBER($O55),$O55*2/SUM($O:$O),"")) | N55: =IF(OR($A55="",$A55="Grand Total"),IF($A55="Grand Total",SUM($N$15:$N54),""),SUMPRODUCT((Table1[County]=SummaryPage!$A55)*(Table1[Status]<>"Complete"))) | O55: =IF($A55="Grand Total",SUM(INDIRECT(ADDRESS(1,COLUMN())&":"&ADDRESS(ROW()-1,COLUMN()))),IF(OR($A55="State Agencies",IFERROR(AND($L55>='Input Sheet'!$J$2,$A55<>""),0)),$J55,"")) | P55: =IF(OR($A55="",$A55="Grand Total"),"",IF(IFERROR(ROUND($J55/$K55,2),1000)>='Input Sheet'!$J$2,1,"")) | Q55: =IFERROR($L55*$P55,"") | R55: =IF(OR($A55="",$A55="Grand Total"),"",AND($J55=0,(SUMPRODUCT((Table1[County]=SummaryPage!$A55)*(Table1[Status]="Not Started"))+SUMPRODUCT((Table1[County]=SummaryPage!$A55)*(Table1[Status]="")))=SUMPRODUCT((Table1[County]=SummaryPage!$A55)*(Table1[Status]<>"Q"))))
K56: =IF($A56="","",VLOOKUP('Input Sheet'!$D$2 & " " & $A56,Pop[#All],4,FALSE)) | L56: =IFERROR(IF($A56="","",ROUND($J56/$K56,2)),"") | M56: =IF(A56="Grand Total","",IF(ISNUMBER($O56),$O56*2/SUM($O:$O),"")) | N56: =IF(OR($A56="",$A56="Grand Total"),IF($A56="Grand Total",SUM($N$15:$N55),""),SUMPRODUCT((Table1[County]=SummaryPage!$A56)*(Table1[Status]<>"Complete"))) | O56: =IF($A56="Grand Total",SUM(INDIRECT(ADDRESS(1,COLUMN())&":"&ADDRESS(ROW()-1,COLUMN()))),IF(OR($A56="State Agencies",IFERROR(AND($L56>='Input Sheet'!$J$2,$A56<>""),0)),$J56,"")) | P56: =IF(OR($A56="",$A56="Grand Total"),"",IF(IFERROR(ROUND($J56/$K56,2),1000)>='Input Sheet'!$J$2,1,"")) | Q56: =IFERROR($L56*$P56,"") | R56: =IF(OR($A56="",$A56="Grand Total"),"",AND($J56=0,(SUMPRODUCT((Table1[County]=SummaryPage!$A56)*(Table1[Status]="Not Started"))+SUMPRODUCT((Table1[County]=SummaryPage!$A56)*(Table1[Status]="")))=SUMPRODUCT((Table1[County]=SummaryPage!$A56)*(Table1[Status]<>"Q"))))
K57: =IF($A57="","",VLOOKUP('Input Sheet'!$D$2 & " " & $A57,Pop[#All],4,FALSE)) | L57: =IFERROR(IF($A57="","",ROUND($J57/$K57,2)),"") | M57: =IF(A57="Grand Total","",IF(ISNUMBER($O57),$O57*2/SUM($O:$O),"")) | N57: =IF(OR($A57="",$A57="Grand Total"),IF($A57="Grand Total",SUM($N$15:$N56),""),SUMPRODUCT((Table1[County]=SummaryPage!$A57)*(Table1[Status]<>"Complete"))) | O57: =IF($A57="Grand Total",SUM(INDIRECT(ADDRESS(1,COLUMN())&":"&ADDRESS(ROW()-1,COLUMN()))),IF(OR($A57="State Agencies",IFERROR(AND($L57>='Input Sheet'!$J$2,$A57<>""),0)),$J57,"")) | P57: =IF(OR($A57="",$A57="Grand Total"),"",IF(IFERROR(ROUND($J57/$K57,2),1000)>='Input Sheet'!$J$2,1,"")) | Q57: =IFERROR($L57*$P57,"") | R57: =IF(OR($A57="",$A57="Grand Total"),"",AND($J57=0,(SUMPRODUCT((Table1[County]=SummaryPage!$A57)*(Table1[Status]="Not Started"))+SUMPRODUCT((Table1[County]=SummaryPage!$A57)*(Table1[Status]="")))=SUMPRODUCT((Table1[County]=SummaryPage!$A57)*(Table1[Status]<>"Q"))))
K58: =IF($A58="","",VLOOKUP('Input Sheet'!$D$2 & " " & $A58,Pop[#All],4,FALSE)) | L58: =IFERROR(IF($A58="","",ROUND($J58/$K58,2)),"") | M58: =IF(A58="Grand Total","",IF(ISNUMBER($O58),$O58*2/SUM($O:$O),"")) | N58: =IF(OR($A58="",$A58="Grand Total"),IF($A58="Grand Total",SUM($N$15:$N57),""),SUMPRODUCT((Table1[County]=SummaryPage!$A58)*(Table1[Status]<>"Complete"))) | O58: =IF($A58="Grand Total",SUM(INDIRECT(ADDRESS(1,COLUMN())&":"&ADDRESS(ROW()-1,COLUMN()))),IF(OR($A58="State Agencies",IFERROR(AND($L58>='Input Sheet'!$J$2,$A58<>""),0)),$J58,"")) | P58: =IF(OR($A58="",$A58="Grand Total"),"",IF(IFERROR(ROUND($J58/$K58,2),1000)>='Input Sheet'!$J$2,1,"")) | Q58: =IFERROR($L58*$P58,"") | R58: =IF(OR($A58="",$A58="Grand Total"),"",AND($J58=0,(SUMPRODUCT((Table1[County]=SummaryPage!$A58)*(Table1[Status]="Not Started"))+SUMPRODUCT((Table1[County]=SummaryPage!$A58)*(Table1[Status]="")))=SUMPRODUCT((Table1[County]=SummaryPage!$A58)*(Table1[Status]<>"Q"))))
K59: =IF($A59="","",VLOOKUP('Input Sheet'!$D$2 & " " & $A59,Pop[#All],4,FALSE)) | L59: =IFERROR(IF($A59="","",ROUND($J59/$K59,2)),"") | M59: =IF(A59="Grand Total","",IF(ISNUMBER($O59),$O59*2/SUM($O:$O),"")) | N59: =IF(OR($A59="",$A59="Grand Total"),IF($A59="Grand Total",SUM($N$15:$N58),""),SUMPRODUCT((Table1[County]=SummaryPage!$A59)*(Table1[Status]<>"Complete"))) | O59: =IF($A59="Grand Total",SUM(INDIRECT(ADDRESS(1,COLUMN())&":"&ADDRESS(ROW()-1,COLUMN()))),IF(OR($A59="State Agencies",IFERROR(AND($L59>='Input Sheet'!$J$2,$A59<>""),0)),$J59,"")) | P59: =IF(OR($A59="",$A59="Grand Total"),"",IF(IFERROR(ROUND($J59/$K59,2),1000)>='Input Sheet'!$J$2,1,"")) | Q59: =IFERROR($L59*$P59,"") | R59: =IF(OR($A59="",$A59="Grand Total"),"",AND($J59=0,(SUMPRODUCT((Table1[County]=SummaryPage!$A59)*(Table1[Status]="Not Started"))+SUMPRODUCT((Table1[County]=SummaryPage!$A59)*(Table1[Status]="")))=SUMPRODUCT((Table1[County]=SummaryPage!$A59)*(Table1[Status]<>"Q"))))
K60: =IF($A60="","",VLOOKUP('Input Sheet'!$D$2 & " " & $A60,Pop[#All],4,FALSE)) | L60: =IFERROR(IF($A60="","",ROUND($J60/$K60,2)),"") | M60: =IF(A60="Grand Total","",IF(ISNUMBER($O60),$O60*2/SUM($O:$O),"")) | N60: =IF(OR($A60="",$A60="Grand Total"),IF($A60="Grand Total",SUM($N$15:$N59),""),SUMPRODUCT((Table1[County]=SummaryPage!$A60)*(Table1[Status]<>"Complete"))) | O60: =IF($A60="Grand Total",SUM(INDIRECT(ADDRESS(1,COLUMN())&":"&ADDRESS(ROW()-1,COLUMN()))),IF(OR($A60="State Agencies",IFERROR(AND($L60>='Input Sheet'!$J$2,$A60<>""),0)),$J60,"")) | P60: =IF(OR($A60="",$A60="Grand Total"),"",IF(IFERROR(ROUND($J60/$K60,2),1000)>='Input Sheet'!$J$2,1,"")) | Q60: =IFERROR($L60*$P60,"") | R60: =IF(OR($A60="",$A60="Grand Total"),"",AND($J60=0,(SUMPRODUCT((Table1[County]=SummaryPage!$A60)*(Table1[Status]="Not Started"))+SUMPRODUCT((Table1[County]=SummaryPage!$A60)*(Table1[Status]="")))=SUMPRODUCT((Table1[County]=SummaryPage!$A60)*(Table1[Status]<>"Q"))))
K61: =IF($A61="","",VLOOKUP('Input Sheet'!$D$2 & " " & $A61,Pop[#All],4,FALSE)) | L61: =IFERROR(IF($A61="","",ROUND($J61/$K61,2)),"") | M61: =IF(A61="Grand Total","",IF(ISNUMBER($O61),$O61*2/SUM($O:$O),"")) | N61: =IF(OR($A61="",$A61="Grand Total"),IF($A61="Grand Total",SUM($N$15:$N60),""),SUMPRODUCT((Table1[County]=SummaryPage!$A61)*(Table1[Status]<>"Complete"))) | O61: =IF($A61="Grand Total",SUM(INDIRECT(ADDRESS(1,COLUMN())&":"&ADDRESS(ROW()-1,COLUMN()))),IF(OR($A61="State Agencies",IFERROR(AND($L61>='Input Sheet'!$J$2,$A61<>""),0)),$J61,"")) | P61: =IF(OR($A61="",$A61="Grand Total"),"",IF(IFERROR(ROUND($J61/$K61,2),1000)>='Input Sheet'!$J$2,1,"")) | Q61: =IFERROR($L61*$P61,"") | R61: =IF(OR($A61="",$A61="Grand Total"),"",AND($J61=0,(SUMPRODUCT((Table1[County]=SummaryPage!$A61)*(Table1[Status]="Not Started"))+SUMPRODUCT((Table1[County]=SummaryPage!$A61)*(Table1[Status]="")))=SUMPRODUCT((Table1[County]=SummaryPage!$A61)*(Table1[Status]<>"Q"))))
K62: =IF($A62="","",VLOOKUP('Input Sheet'!$D$2 & " " & $A62,Pop[#All],4,FALSE)) | L62: =IFERROR(IF($A62="","",ROUND($J62/$K62,2)),"") | M62: =IF(A62="Grand Total","",IF(ISNUMBER($O62),$O62*2/SUM($O:$O),"")) | N62: =IF(OR($A62="",$A62="Grand Total"),IF($A62="Grand Total",SUM($N$15:$N61),""),SUMPRODUCT((Table1[County]=SummaryPage!$A62)*(Table1[Status]<>"Complete"))) | O62: =IF($A62="Grand Total",SUM(INDIRECT(ADDRESS(1,COLUMN())&":"&ADDRESS(ROW()-1,COLUMN()))),IF(OR($A62="State Agencies",IFERROR(AND($L62>='Input Sheet'!$J$2,$A62<>""),0)),$J62,"")) | P62: =IF(OR($A62="",$A62="Grand Total"),"",IF(IFERROR(ROUND($J62/$K62,2),1000)>='Input Sheet'!$J$2,1,"")) | Q62: =IFERROR($L62*$P62,"") | R62: =IF(OR($A62="",$A62="Grand Total"),"",AND($J62=0,(SUMPRODUCT((Table1[County]=SummaryPage!$A62)*(Table1[Status]="Not Started"))+SUMPRODUCT((Table1[County]=SummaryPage!$A62)*(Table1[Status]="")))=SUMPRODUCT((Table1[County]=SummaryPage!$A62)*(Table1[Status]<>"Q"))))
K63: =IF($A63="","",VLOOKUP('Input Sheet'!$D$2 & " " & $A63,Pop[#All],4,FALSE)) | L63: =IFERROR(IF($A63="","",ROUND($J63/$K63,2)),"") | M63: =IF(A63="Grand Total","",IF(ISNUMBER($O63),$O63*2/SUM($O:$O),"")) | N63: =IF(OR($A63="",$A63="Grand Total"),IF($A63="Grand Total",SUM($N$15:$N62),""),SUMPRODUCT((Table1[County]=SummaryPage!$A63)*(Table1[Status]<>"Complete"))) | O63: =IF($A63="Grand Total",SUM(INDIRECT(ADDRESS(1,COLUMN())&":"&ADDRESS(ROW()-1,COLUMN()))),IF(OR($A63="State Agencies",IFERROR(AND($L63>='Input Sheet'!$J$2,$A63<>""),0)),$J63,"")) | P63: =IF(OR($A63="",$A63="Grand Total"),"",IF(IFERROR(ROUND($J63/$K63,2),1000)>='Input Sheet'!$J$2,1,"")) | Q63: =IFERROR($L63*$P63,"") | R63: =IF(OR($A63="",$A63="Grand Total"),"",AND($J63=0,(SUMPRODUCT((Table1[County]=SummaryPage!$A63)*(Table1[Status]="Not Started"))+SUMPRODUCT((Table1[County]=SummaryPage!$A63)*(Table1[Status]="")))=SUMPRODUCT((Table1[County]=SummaryPage!$A63)*(Table1[Status]<>"Q"))))
K64: =IF($A64="","",VLOOKUP('Input Sheet'!$D$2 & " " & $A64,Pop[#All],4,FALSE)) | L64: =IFERROR(IF($A64="","",ROUND($J64/$K64,2)),"") | M64: =IF(A64="Grand Total","",IF(ISNUMBER($O64),$O64*2/SUM($O:$O),"")) | N64: =IF(OR($A64="",$A64="Grand Total"),IF($A64="Grand Total",SUM($N$15:$N63),""),SUMPRODUCT((Table1[County]=SummaryPage!$A64)*(Table1[Status]<>"Complete"))) | O64: =IF($A64="Grand Total",SUM(INDIRECT(ADDRESS(1,COLUMN())&":"&ADDRESS(ROW()-1,COLUMN()))),IF(OR($A64="State Agencies",IFERROR(AND($L64>='Input Sheet'!$J$2,$A64<>""),0)),$J64,"")) | P64: =IF(OR($A64="",$A64="Grand Total"),"",IF(IFERROR(ROUND($J64/$K64,2),1000)>='Input Sheet'!$J$2,1,"")) | Q64: =IFERROR($L64*$P64,"") | R64: =IF(OR($A64="",$A64="Grand Total"),"",AND($J64=0,(SUMPRODUCT((Table1[County]=SummaryPage!$A64)*(Table1[Status]="Not Started"))+SUMPRODUCT((Table1[County]=SummaryPage!$A64)*(Table1[Status]="")))=SUMPRODUCT((Table1[County]=SummaryPage!$A64)*(Table1[Status]<>"Q"))))
... K904: =IF($A904="","",VLOOKUP('Input Sheet'!$D$2 & " " & $A904,Pop[#All],4,FALSE)) | L904: =IFERROR(IF($A904="","",ROUND($J904/$K904,2)),"") | M904: =IF(A904="Grand Total","",IF(ISNUMBER($O904),$O904*2/SUM($O:$O),"")) | N904: =IF(OR($A904="",$A904="Grand Total"),IF($A904="Grand Total",SUM($N$15:$N903),""),SUMPRODUCT((Table1[County]=SummaryPage!$A904)*(Table1[Status]<>"Complete"))) | O904: =IF($A904="Grand Total",SUM(INDIRECT(ADDRESS(1,COLUMN())&":"&ADDRESS(ROW()-1,COLUMN()))),IF(OR($A904="State Agencies",IFERROR(AND($L904>='Input Sheet'!$J$2,$A904<>""),0)),$J904,"")) | P904: =IF(OR($A904="",$A904="Grand Total"),"",IF(IFERROR(ROUND($J904/$K904,2),1000)>='Input Sheet'!$J$2,1,"")) | Q904: =IFERROR($L904*$P904,"") | R904: =IF(OR($A904="",$A904="Grand Total"),"",AND($J904=0,(SUMPRODUCT((Table1[County]=SummaryPage!$A904)*(Table1[Status]="Not Started"))+SUMPRODUCT((Table1[County]=SummaryPage!$A904)*(Table1[Status]="")))=SUMPRODUCT((Table1[County]=SummaryPage!$A904)*(Table1[Status]<>"Q"))))
...

Sheet Input Sheet
A1: DATA ENTRY: | C1: Region: | D1: 5 | E1: Event Type: | F1: Flood | G1: Incident Start: | H1: 46122 | I1: State Per Capita: | J1: 1.94 | K1: 94 Applicants
C2: State Code: | D2: MI | E2: PDA Start: | F2: 46161 | G2: Incident End: | H2: 46133 | I2: County Per Capita: | J2: 4.86
A3: START DATA IN GRAY AREA (ROW 5) | K3: {=_xlfn.CONCAT(SUM(1/COUNTIFS(B5:B123,B5:B123))," Counties")} -> 37 Counties
A4: Subrecipient | B4: County | C4: Status | D4: A | E4: B | F4: C | G4: D | H4: E | I4: F | J4: G
A5: Alcona County Road Commission | B5: Alcona | C5: Complete | E5: 78740.63 | F5: 370322.78
A6: PIE&G - Alcona | B6: Alcona | C6: Complete | E6: 836
A7: City of Douglas | B7: Allegan | C7: Complete | F7: 89967
A8: City of Plainwell | B8: Allegan | C8: Complete | D8: 33497.3
A9: Gun Plain Township | B9: Allegan | C9: Complete | D9: 70650 | G9: 20282
A10: Alpena Road Commission | B10: Alpena | C10: Complete | F10: 147388
A11: Alpena, City of | B11: Alpena | C11: Complete | G11: 73375.93
A12: Antrim County | B12: Antrim | C12: Complete | E12: 28062.99 | G12: 20183.44
A13: Village of Bellaire | B13: Antrim | C13: Complete
A14: Benzie County Road Commission | B14: Benzie | C14: Complete
A15: Benzonia Township | B15: Benzie | C15: Complete | J15: 7812
A16: Betsie Valley Trail | B16: Benzie | C16: Complete
A17: Homstead Dam - Benzie Labor emergency protective measures | B17: Benzie | C17: Complete
A18: MDNR - Benzie County | B18: Benzie | C18: Complete | G18: 35892.62
A19: Village of Beulah | B19: Benzie | C19: Complete | I19: 187982
A20: Charlevoix County Road Commission | B20: Charlevoix | C20: Complete | F20: 190676.5
A21: City of Charlevoix | B21: Charlevoix | C21: Complete | I21: 0
A22: City of East Jordan | B22: Charlevoix | C22: Complete | I22: 7936
A23: St. James Township | B23: Charlevoix | C23: Complete | G23: 26145
A24: Cheboygan County Road Commission | B24: Cheboygan | C24: Complete | E24: 31621 | F24: 905964
A25: Cheboygan EOC | B25: Cheboygan | C25: Complete | D25: 350000 | E25: 48044.53
A26: MDNR - Cheboygan County | B26: Cheboygan | C26: Complete | D26: 470369.85 | E26: 5084849.5 | G26: 624844.77 | J26: 604436
A27: Michigan State Police - Cheboygan | B27: Cheboygan | C27: Complete | E27: 66516
A28: PIE&G - Cheboygan | B28: Cheboygan | C28: Complete | I28: 66138
A29: Tuscarora Township | B29: Cheboygan | C29: Complete | D29: 0 | E29: 24657.62 | F29: 0 | J29: 185467
A30: Clare County Road Commission | B30: Clare | C30: Complete | F30: 38906.37
A31: Great Lakes Energy Co-Op - Clare | B31: Clare | C31: Complete | I31: 4075
A32: Au Sable Woods Association | B32: Crawford | C32: Complete | F32: 20080
A33: Crawford County | B33: Crawford | C33: Complete | E33: 5500
A34: Crawford Road Commission | B34: Crawford | C34: Complete | F34: 29208
A35: MDNR- Crawford County | B35: Crawford | C35: Complete | J35: 804
A36: South Branch Fire Dept | B36: Crawford | C36: Complete | E36: 11923
A37: Eaton County Drain Commission | B37: Eaton | C37: Complete
A38: Eaton County Road Commission | B38: Eaton | C38: Complete | E38: 8565.56 | F38: 503921.9
A39: EGLE - Eaton County | B39: Eaton | C39: Complete | E39: 15666.48
A40: Michigan State Police EOC - Eaton County | B40: Eaton | C40: Complete | E40: 172059
...

Sheet Applicants
A1: Applicant | B1: Count
A2: Alcona County Road Commission | B2: 1
A3: PIE&G - Alcona | B3: 1
A4: City of Douglas | B4: 1
A5: City of Plainwell | B5: 1
A6: Gun Plain Township | B6: 1
A7: Alpena Road Commission | B7: 1
A8: Alpena, City of | B8: 1
A9: Village of Bellaire | B9: 1
A10: Antrim County | B10: 1
A11: Benzie County Road Commission | B11: 1
A12: Benzonia Township | B12: 1
A13: Betsie Valley Trail | B13: 1
... A120: Village of Kalkaska | B120: 1
B121: =SUBTOTAL(109,Table14[Count]) -> 99

Sheet Reductions
E1: Total Reductions | G1: =SUM(Table4[Reduction]) -> 0
B2: County | C2: Applicant | D2: Cat | E2: Original | F2: Eligible | G2: Reduction | H2: Reduction Category | I2: Notes
G86: =Table4[[#This Row],[Eligible]]-Table4[[#This Row],[Original]] -> 0
G87: =Table4[[#This Row],[Eligible]]-Table4[[#This Row],[Original]] -> 0
G88: =Table4[[#This Row],[Eligible]]-Table4[[#This Row],[Original]] -> 0
G89: =Table4[[#This Row],[Eligible]]-Table4[[#This Row],[Original]] -> 0
G90: =Table4[[#This Row],[Eligible]]-Table4[[#This Row],[Original]] -> 0

Sheet Summary
A1: MI PDA - May 2026
A3: Timeline | B3: Date
A4: Incident Period | B4: April 10 - 21, 2026
A5: PDA Timeline | B5: May 19 - 30, 2026
A7: PDA Stats - Indiana | B7: Total
A8: Applicants | B8: 94 | D8: Map | E8: Map
A9: Counties | B9: 37
A11: Total & State Threshold | B11: Total
A12: PDA Total | B12: 23494514
A13: State Threshold | B13: =SummaryPage!K7*Summary!B16 -> 19550022
A15: Indicators & Projects | B15: Total
A16: Statewide Indicator | B16: 1.94 | D16: County | E16: Total
A17: Countywide Indicator | B17: 4.86 | D17: Alcona | E17: =SUMIFS(Table1[A], Table1[County], Table114[[#This Row],[County]]) +SUMIFS(Table1[B], Table1[County], Table114[[#This Row],[County]]) +SUMIFS(Table1[C], Table1[County], Table114[[#This Row],[County]]) +SUMIFS(Table1[D], Table1[County], Table114[[#This Row],[County]]) +SUMIFS(Table1[E], Table1[County], Table114[[#This Row],[County]]) +SUMIFS(Table1[F], Table1[County], Table114[[#This Row],[County]]) +SUMIFS(Table1[G], Table1[County], Table114[[#This Row],[County]]) -> 449899.41
A18: Small Project Minimum | B18: 4100 | D18: Allegan | E18: =SUMIFS(Table1[A], Table1[County], Table114[[#This Row],[County]]) +SUMIFS(Table1[B], Table1[County], Table114[[#This Row],[County]]) +SUMIFS(Table1[C], Table1[County], Table114[[#This Row],[County]]) +SUMIFS(Table1[D], Table1[County], Table114[[#This Row],[County]]) +SUMIFS(Table1[E], Table1[County], Table114[[#This Row],[County]]) +SUMIFS(Table1[F], Table1[County], Table114[[#This Row],[County]]) +SUMIFS(Table1[G], Table1[County], Table114[[#This Row],[County]]) -> 214396.3
A19: Large Project Threshold | B19: 1093800 | D19: Alpena | E19: =SUMIFS(Table1[A], Table1[County], Table114[[#This Row],[County]]) +SUMIFS(Table1[B], Table1[County], Table114[[#This Row],[County]]) +SUMIFS(Table1[C], Table1[County], Table114[[#This Row],[County]]) +SUMIFS(Table1[D], Table1[County], Table114[[#This Row],[County]]) +SUMIFS(Table1[E], Table1[County], Table114[[#This Row],[County]]) +SUMIFS(Table1[F], Table1[County], Table114[[#This Row],[County]]) +SUMIFS(Table1[G], Table1[County], Table114[[#This Row],[County]]) -> 220763.93
D20: Antrim | E20: =SUMIFS(Table1[A], Table1[County], Table114[[#This Row],[County]]) +SUMIFS(Table1[B], Table1[County], Table114[[#This Row],[County]]) +SUMIFS(Table1[C], Table1[County], Table114[[#This Row],[County]]) +SUMIFS(Table1[D], Table1[County], Table114[[#This Row],[County]]) +SUMIFS(Table1[E], Table1[County], Table114[[#This Row],[County]]) +SUMIFS(Table1[F], Table1[County], Table114[[#This Row],[County]]) +SUMIFS(Table1[G], Table1[County], Table114[[#This Row],[County]]) -> 48246.43
A21: Damage Category | B21: Total | D21: Arenac | E21: =SUMIFS(Table1[A], Table1[County], Table114[[#This Row],[County]]) +SUMIFS(Table1[B], Table1[County], Table114[[#This Row],[County]]) +SUMIFS(Table1[C], Table1[County], Table114[[#This Row],[County]]) +SUMIFS(Table1[D], Table1[County], Table114[[#This Row],[County]]) +SUMIFS(Table1[E], Table1[County], Table114[[#This Row],[County]]) +SUMIFS(Table1[F], Table1[County], Table114[[#This Row],[County]]) +SUMIFS(Table1[G], Table1[County], Table114[[#This Row],[County]]) -> 0
A22: Category A | B22: 1072897 | D22: Barry | E22: =SUMIFS(Table1[A], Table1[County], Table114[[#This Row],[County]]) +SUMIFS(Table1[B], Table1[County], Table114[[#This Row],[County]]) +SUMIFS(Table1[C], Table1[County], Table114[[#This Row],[County]]) +SUMIFS(Table1[D], Table1[County], Table114[[#This Row],[County]]) +SUMIFS(Table1[E], Table1[County], Table114[[#This Row],[County]]) +SUMIFS(Table1[F], Table1[County], Table114[[#This Row],[County]]) +SUMIFS(Table1[G], Table1[County], Table114[[#This Row],[County]]) -> 0
A23: Category B | B23: 6509052 | D23: Benzie | E23: =SUMIFS(Table1[A], Table1[County], Table114[[#This Row],[County]]) +SUMIFS(Table1[B], Table1[County], Table114[[#This Row],[County]]) +SUMIFS(Table1[C], Table1[County], Table114[[#This Row],[County]]) +SUMIFS(Table1[D], Table1[County], Table114[[#This Row],[County]]) +SUMIFS(Table1[E], Table1[County], Table114[[#This Row],[County]]) +SUMIFS(Table1[F], Table1[County], Table114[[#This Row],[County]]) +SUMIFS(Table1[G], Table1[County], Table114[[#This Row],[County]]) -> 231686.62
A24: Category C | B24: =44948+11161420 -> 11206368 | D24: Charlevoix | E24: =SUMIFS(Table1[A], Table1[County], Table114[[#This Row],[County]]) +SUMIFS(Table1[B], Table1[County], Table114[[#This Row],[County]]) +SUMIFS(Table1[C], Table1[County], Table114[[#This Row],[County]]) +SUMIFS(Table1[D], Table1[County], Table114[[#This Row],[County]]) +SUMIFS(Table1[E], Table1[County], Table114[[#This Row],[County]]) +SUMIFS(Table1[F], Table1[County], Table114[[#This Row],[County]]) +SUMIFS(Table1[G], Table1[County], Table114[[#This Row],[County]]) -> 224757.5
A25: Category D | B25: 1113982 | D25: Cheboygan | E25: =SUMIFS(Table1[A], Table1[County], Table114[[#This Row],[County]]) +SUMIFS(Table1[B], Table1[County], Table114[[#This Row],[County]]) +SUMIFS(Table1[C], Table1[County], Table114[[#This Row],[County]]) +SUMIFS(Table1[D], Table1[County], Table114[[#This Row],[County]]) +SUMIFS(Table1[E], Table1[County], Table114[[#This Row],[County]]) +SUMIFS(Table1[F], Table1[County], Table114[[#This Row],[County]]) +SUMIFS(Table1[G], Table1[County], Table114[[#This Row],[County]]) -> 8462908.2
A26: Category E | B26: 158956 | D26: Clare | E26: =SUMIFS(Table1[A], Table1[County], Table114[[#This Row],[County]]) +SUMIFS(Table1[B], Table1[County], Table114[[#This Row],[County]]) +SUMIFS(Table1[C], Table1[County], Table114[[#This Row],[County]]) +SUMIFS(Table1[D], Table1[County], Table114[[#This Row],[County]]) +SUMIFS(Table1[E], Table1[County], Table114[[#This Row],[County]]) +SUMIFS(Table1[F], Table1[County], Table114[[#This Row],[County]]) +SUMIFS(Table1[G], Table1[County], Table114[[#This Row],[County]]) -> 42981.37
A27: Category F | B27: 781898 | D27: Crawford | E27: =SUMIFS(Table1[A], Table1[County], Table114[[#This Row],[County]]) +SUMIFS(Table1[B], Table1[County], Table114[[#This Row],[County]]) +SUMIFS(Table1[C], Table1[County], Table114[[#This Row],[County]]) +SUMIFS(Table1[D], Table1[County], Table114[[#This Row],[County]]) +SUMIFS(Table1[E], Table1[County], Table114[[#This Row],[County]]) +SUMIFS(Table1[F], Table1[County], Table114[[#This Row],[County]]) +SUMIFS(Table1[G], Table1[County], Table114[[#This Row],[County]]) -> 67515
A28: Category G | B28: =33625+2617735 -> 2651360 | D28: Eaton | E28: =SUMIFS(Table1[A], Table1[County], Table114[[#This Row],[County]]) +SUMIFS(Table1[B], Table1[County], Table114[[#This Row],[County]]) +SUMIFS(Table1[C], Table1[County], Table114[[#This Row],[County]]) +SUMIFS(Table1[D], Table1[County], Table114[[#This Row],[County]]) +SUMIFS(Table1[E], Table1[County], Table114[[#This Row],[County]]) +SUMIFS(Table1[F], Table1[County], Table114[[#This Row],[County]]) +SUMIFS(Table1[G], Table1[County], Table114[[#This Row],[County]]) -> 824477.04
D29: Emmet | E29: =SUMIFS(Table1[A], Table1[County], Table114[[#This Row],[County]]) +SUMIFS(Table1[B], Table1[County], Table114[[#This Row],[County]]) +SUMIFS(Table1[C], Table1[County], Table114[[#This Row],[County]]) +SUMIFS(Table1[D], Table1[County], Table114[[#This Row],[County]]) +SUMIFS(Table1[E], Table1[County], Table114[[#This Row],[County]]) +SUMIFS(Table1[F], Table1[County], Table114[[#This Row],[County]]) +SUMIFS(Table1[G], Table1[County], Table114[[#This Row],[County]]) -> 278017.66
A30: FEMA Team | B30: State Team | D30: Grand Traverse | E30: =SUMIFS(Table1[A], Table1[County], Table114[[#This Row],[County]]) +SUMIFS(Table1[B], Table1[County], Table114[[#This Row],[County]]) +SUMIFS(Table1[C], Table1[County], Table114[[#This Row],[County]]) +SUMIFS(Table1[D], Table1[County], Table114[[#This Row],[County]]) +SUMIFS(Table1[E], Table1[County], Table114[[#This Row],[County]]) +SUMIFS(Table1[F], Table1[County], Table114[[#This Row],[County]]) +SUMIFS(Table1[G], Table1[County], Table114[[#This Row],[County]]) -> 2690331
A31: Jennie Grobe | B31: Marisela Shellenbarger | D31: Gratiot | E31: =SUMIFS(Table1[A], Table1[County], Table114[[#This Row],[County]]) +SUMIFS(Table1[B], Table1[County], Table114[[#This Row],[County]]) +SUMIFS(Table1[C], Table1[County], Table114[[#This Row],[County]]) +SUMIFS(Table1[D], Table1[County], Table114[[#This Row],[County]]) +SUMIFS(Table1[E], Table1[County], Table114[[#This Row],[County]]) +SUMIFS(Table1[F], Table1[County], Table114[[#This Row],[County]]) +SUMIFS(Table1[G], Table1[County], Table114[[#This Row],[County]]) -> 206180.91
A32: Katie Warren | D32: Iosco | E32: =SUMIFS(Table1[A], Table1[County], Table114[[#This Row],[County]]) +SUMIFS(Table1[B], Table1[County], Table114[[#This Row],[County]]) +SUMIFS(Table1[C], Table1[County], Table114[[#This Row],[County]]) +SUMIFS(Table1[D], Table1[County], Table114[[#This Row],[County]]) +SUMIFS(Table1[E], Table1[County], Table114[[#This Row],[County]]) +SUMIFS(Table1[F], Table1[County], Table114[[#This Row],[County]]) +SUMIFS(Table1[G], Table1[County], Table114[[#This Row],[County]]) -> 0
A33: Roopak Hanna | D33: Iron | E33: =SUMIFS(Table1[A], Table1[County], Table114[[#This Row],[County]]) +SUMIFS(Table1[B], Table1[County], Table114[[#This Row],[County]]) +SUMIFS(Table1[C], Table1[County], Table114[[#This Row],[County]]) +SUMIFS(Table1[D], Table1[County], Table114[[#This Row],[County]]) +SUMIFS(Table1[E], Table1[County], Table114[[#This Row],[County]]) +SUMIFS(Table1[F], Table1[County], Table114[[#This Row],[County]]) +SUMIFS(Table1[G], Table1[County], Table114[[#This Row],[County]]) -> 383314
A34: Maxwell Novoselac | D34: Jackson | E34: =SUMIFS(Table1[A], Table1[County], Table114[[#This Row],[County]]) +SUMIFS(Table1[B], Table1[County], Table114[[#This Row],[County]]) +SUMIFS(Table1[C], Table1[County], Table114[[#This Row],[County]]) +SUMIFS(Table1[D], Table1[County], Table114[[#This Row],[County]]) +SUMIFS(Table1[E], Table1[County], Table114[[#This Row],[County]]) +SUMIFS(Table1[F], Table1[County], Table114[[#This Row],[County]]) +SUMIFS(Table1[G], Table1[County], Table114[[#This Row],[County]]) -> 241438
A35: Charlie Annerino | D35: Kalamazoo | E35: =SUMIFS(Table1[A], Table1[County], Table114[[#This Row],[County]]) +SUMIFS(Table1[B], Table1[County], Table114[[#This Row],[County]]) +SUMIFS(Table1[C], Table1[County], Table114[[#This Row],[County]]) +SUMIFS(Table1[D], Table1[County], Table114[[#This Row],[County]]) +SUMIFS(Table1[E], Table1[County], Table114[[#This Row],[County]]) +SUMIFS(Table1[F], Table1[County], Table114[[#This Row],[County]]) +SUMIFS(Table1[G], Table1[County], Table114[[#This Row],[County]]) -> 18537
A36: Caleb Smith | D36: Kalkaska | E36: =SUMIFS(Table1[A], Table1[County], Table114[[#This Row],[County]]) +SUMIFS(Table1[B], Table1[County], Table114[[#This Row],[County]]) +SUMIFS(Table1[C], Table1[County], Table114[[#This Row],[County]]) +SUMIFS(Table1[D], Table1[County], Table114[[#This Row],[County]]) +SUMIFS(Table1[E], Table1[County], Table114[[#This Row],[County]]) +SUMIFS(Table1[F], Table1[County], Table114[[#This Row],[County]]) +SUMIFS(Table1[G], Table1[County], Table114[[#This Row],[County]]) -> 372064.86
A37: Connor Blevins | D37: Lake | E37: =SUMIFS(Table1[A], Table1[County], Table114[[#This Row],[County]]) +SUMIFS(Table1[B], Table1[County], Table114[[#This Row],[County]]) +SUMIFS(Table1[C], Table1[County], Table114[[#This Row],[County]]) +SUMIFS(Table1[D], Table1[County], Table114[[#This Row],[County]]) +SUMIFS(Table1[E], Table1[County], Table114[[#This Row],[County]]) +SUMIFS(Table1[F], Table1[County], Table114[[#This Row],[County]]) +SUMIFS(Table1[G], Table1[County], Table114[[#This Row],[County]]) -> 137336.87
A38: Anessa Jones | D38: Leelanau | E38: =SUMIFS(Table1[A], Table1[County], Table114[[#This Row],[County]]) +SUMIFS(Table1[B], Table1[County], Table114[[#This Row],[County]]) +SUMIFS(Table1[C], Table1[County], Table114[[#This Row],[County]]) +SUMIFS(Table1[D], Table1[County], Table114[[#This Row],[County]]) +SUMIFS(Table1[E], Table1[County], Table114[[#This Row],[County]]) +SUMIFS(Table1[F], Table1[County], Table114[[#This Row],[County]]) +SUMIFS(Table1[G], Table1[County], Table114[[#This Row],[County]]) -> 5858.15
A39: Ja'von Cotton | D39: Manistee | E39: =SUMIFS(Table1[A], Table1[County], Table114[[#This Row],[County]]) +SUMIFS(Table1[B], Table1[County], Table114[[#This Row],[County]]) +SUMIFS(Table1[C], Table1[County], Table114[[#This Row],[County]]) +SUMIFS(Table1[D], Table1[County], Table114[[#This Row],[County]]) +SUMIFS(Table1[E], Table1[County], Table114[[#This Row],[County]]) +SUMIFS(Table1[F], Table1[County], Table114[[#This Row],[County]]) +SUMIFS(Table1[G], Table1[County], Table114[[#This Row],[County]]) -> 1952971.6
A40: Eric Punzalan | D40: Marquette | E40: =SUMIFS(Table1[A], Table1[County], Table114[[#This Row],[County]]) +SUMIFS(Table1[B], Table1[County], Table114[[#This Row],[County]]) +SUMIFS(Table1[C], Table1[County], Table114[[#This Row],[County]]) +SUMIFS(Table1[D], Table1[County], Table114[[#This Row],[County]]) +SUMIFS(Table1[E], Table1[County], Table114[[#This Row],[County]]) +SUMIFS(Table1[F], Table1[County], Table114[[#This Row],[County]]) +SUMIFS(Table1[G], Table1[County], Table114[[#This Row],[County]]) -> 400562
A41: Angela Williams | D41: Mecosta | E41: =SUMIFS(Table1[A], Table1[County], Table114[[#This Row],[County]]) +SUMIFS(Table1[B], Table1[County], Table114[[#This Row],[County]]) +SUMIFS(Table1[C], Table1[County], Table114[[#This Row],[County]]) +SUMIFS(Table1[D], Table1[County], Table114[[#This Row],[County]]) +SUMIFS(Table1[E], Table1[County], Table114[[#This Row],[County]]) +SUMIFS(Table1[F], Table1[County], Table114[[#This Row],[County]]) +SUMIFS(Table1[G], Table1[County], Table114[[#This Row],[County]]) -> 632000
A42: Sam Efein | D42: Menominee | E42: =SUMIFS(Table1[A], Table1[County], Table114[[#This Row],[County]]) +SUMIFS(Table1[B], Table1[County], Table114[[#This Row],[County]]) +SUMIFS(Table1[C], Table1[County], Table114[[#This Row],[County]]) +SUMIFS(Table1[D], Table1[County], Table114[[#This Row],[County]]) +SUMIFS(Table1[E], Table1[County], Table114[[#This Row],[County]]) +SUMIFS(Table1[F], Table1[County], Table114[[#This Row],[County]]) +SUMIFS(Table1[G], Table1[County], Table114[[#This Row],[County]]) -> 403474
A43: Mike Richards | D43: Missaukee | E43: =SUMIFS(Table1[A], Table1[County], Table114[[#This Row],[County]]) +SUMIFS(Table1[B], Table1[County], Table114[[#This Row],[County]]) +SUMIFS(Table1[C], Table1[County], Table114[[#This Row],[County]]) +SUMIFS(Table1[D], Table1[County], Table114[[#This Row],[County]]) +SUMIFS(Table1[E], Table1[County], Table114[[#This Row],[County]]) +SUMIFS(Table1[F], Table1[County], Table114[[#This Row],[County]]) +SUMIFS(Table1[G], Table1[County], Table114[[#This Row],[County]]) -> 286453
A44: Alexis Villasenor | D44: Montcalm | E44: =SUMIFS(Table1[A], Table1[County], Table114[[#This Row],[County]]) +SUMIFS(Table1[B], Table1[County], Table114[[#This Row],[County]]) +SUMIFS(Table1[C], Table1[County], Table114[[#This Row],[County]]) +SUMIFS(Table1[D], Table1[County], Table114[[#This Row],[County]]) +SUMIFS(Table1[E], Table1[County], Table114[[#This Row],[County]]) +SUMIFS(Table1[F], Table1[County], Table114[[#This Row],[County]]) +SUMIFS(Table1[G], Table1[County], Table114[[#This Row],[County]]) -> 51963.65
...

Sheet PCI Indicator
A1: Public Assistance Preliminary Damage Assessments (PDA)
A3: STATE/TERRITORY | B3: POPULATION | C3: STATE PCI | D3: COUNTY PCI | E3: STATUS
A4: Michigan | B4: 10077331 | C4: 1.94 | D4: 4.86 | E4: TBD
A6: INCIDENT NAME | B6: Date | C6: INCIDENT START | D6: INCIDENT END DATE | E6: INCIDENT TYPE
A7: TBD | B7: TBD | C7: 46122 | D7: ='Input Sheet'!H2 -> 46133 | E7: ='Input Sheet'!F1 -> Flood
A9: FACTOR | B9: TOTAL | C9: POPULATION | D9: STATE PCI | E9: STATE PCI TARGET | F9: % STATE PCI Target | G9: PERCENT STATE PCI
A10: Met PCI | B10: =SUMIF(F14:F56, ">1", C14:C56) -> 23415940 | C10: =B4 -> 10077331 | D10: 1.94 | E10: =D10*C10 -> 19550022 | F10: >=75 | G10: =B10/E10 -> 1.1977449
A11: Met or Exceeded 50% PCI | B11: =SUMIFS(C14:C56, F14:F56, "<1", F14:F56, ">.4999999999" ) -> 78573.08 | C11: =SUMIFS(B14:B56, F14:F56, "<1", F14:F56, ">.4999999999" ) -> 23459 | D11: 1.94 | E11: =D11*C11 -> 45510.46 | F11: >=100 | G11: =IFERROR(B11/E11, 0) -> 1.726484
A13: COUNTY | B13: POPULATION | C13: VALIDATED COSTS | D13: COUNTY PCI | E13: COUNTY PCI TARGET | F13: MEETS 100% INDICATOR | G13: MEETS 50% INDICATOR
A14: Alcona | B14: 10167 | C14: =SUMIFS(Table1[A], Table1[County], A14) +SUMIFS(Table1[B], Table1[County], A14) +SUMIFS(Table1[C], Table1[County], A14) +SUMIFS(Table1[D], Table1[County], A14) +SUMIFS(Table1[E], Table1[County], A14) +SUMIFS(Table1[F], Table1[County], A14) +SUMIFS(Table1[G], Table1[County], A14) -> 449899.41 | D14: 4.86 | E14: =D14*B14 -> 49411.62 | F14: =IFERROR(C14/E14, "TBC") -> 9.1051338 | G14: =C14/E14 -> 9.1051338
A15: Alpena | B15: 28907 | C15: =SUMIFS(Table1[A], Table1[County], A15) +SUMIFS(Table1[B], Table1[County], A15) +SUMIFS(Table1[C], Table1[County], A15) +SUMIFS(Table1[D], Table1[County], A15) +SUMIFS(Table1[E], Table1[County], A15) +SUMIFS(Table1[F], Table1[County], A15) +SUMIFS(Table1[G], Table1[County], A15) -> 220763.93 | D15: 4.86 | E15: =D15*B15 -> 140488.02 | F15: =IFERROR(C15/E15, "TBC") -> 1.5714075 | G15: =C15/E15 -> 1.5714075
A16: Benzie | B16: 17970 | C16: =SUMIFS(Table1[A], Table1[County], A16) +SUMIFS(Table1[B], Table1[County], A16) +SUMIFS(Table1[C], Table1[County], A16) +SUMIFS(Table1[D], Table1[County], A16) +SUMIFS(Table1[E], Table1[County], A16) +SUMIFS(Table1[F], Table1[County], A16) +SUMIFS(Table1[G], Table1[County], A16) -> 231686.62 | D16: 4.86 | E16: =D16*B16 -> 87334.2 | F16: =IFERROR(C16/E16, "TBC") -> 2.6528739 | G16: =C16/E16 -> 2.6528739
A17: Charlevoix | B17: 26054 | C17: =SUMIFS(Table1[A], Table1[County], A17) +SUMIFS(Table1[B], Table1[County], A17) +SUMIFS(Table1[C], Table1[County], A17) +SUMIFS(Table1[D], Table1[County], A17) +SUMIFS(Table1[E], Table1[County], A17) +SUMIFS(Table1[F], Table1[County], A17) +SUMIFS(Table1[G], Table1[County], A17) -> 224757.5 | D17: 4.86 | E17: =D17*B17 -> 126622.44 | F17: =IFERROR(C17/E17, "TBC") -> 1.7750211 | G17: =C17/E17 -> 1.7750211
A18: Cheboygan | B18: 25579 | C18: =SUMIFS(Table1[A], Table1[County], A18) +SUMIFS(Table1[B], Table1[County], A18) +SUMIFS(Table1[C], Table1[County], A18) +SUMIFS(Table1[D], Table1[County], A18) +SUMIFS(Table1[E], Table1[County], A18) +SUMIFS(Table1[F], Table1[County], A18) +SUMIFS(Table1[G], Table1[County], A18) -> 8462908.2 | D18: 4.86 | E18: =D18*B18 -> 124313.94 | F18: =IFERROR(C18/E18, "TBC") -> 68.076904 | G18: =C18/E18 -> 68.076904
A19: Crawford | B19: 12988 | C19: =SUMIFS(Table1[A], Table1[County], A19) +SUMIFS(Table1[B], Table1[County], A19) +SUMIFS(Table1[C], Table1[County], A19) +SUMIFS(Table1[D], Table1[County], A19) +SUMIFS(Table1[E], Table1[County], A19) +SUMIFS(Table1[F], Table1[County], A19) +SUMIFS(Table1[G], Table1[County], A19) -> 67515 | D19: 4.86 | E19: =D19*B19 -> 63121.68 | F19: =IFERROR(C19/E19, "TBC") -> 1.0696008 | G19: =C19/E19 -> 1.0696008
A20: Eaton | B20: 109175 | C20: =SUMIFS(Table1[A], Table1[County], A20) +SUMIFS(Table1[B], Table1[County], A20) +SUMIFS(Table1[C], Table1[County], A20) +SUMIFS(Table1[D], Table1[County], A20) +SUMIFS(Table1[E], Table1[County], A20) +SUMIFS(Table1[F], Table1[County], A20) +SUMIFS(Table1[G], Table1[County], A20) -> 824477.04 | D20: 4.86 | E20: =D20*B20 -> 530590.5 | F20: =IFERROR(C20/E20, "TBC") -> 1.5538858 | G20: =C20/E20 -> 1.5538858
A21: Emmet | B21: 34112 | C21: =SUMIFS(Table1[A], Table1[County], A21) +SUMIFS(Table1[B], Table1[County], A21) +SUMIFS(Table1[C], Table1[County], A21) +SUMIFS(Table1[D], Table1[County], A21) +SUMIFS(Table1[E], Table1[County], A21) +SUMIFS(Table1[F], Table1[County], A21) +SUMIFS(Table1[G], Table1[County], A21) -> 278017.66 | D21: 4.86 | E21: =D21*B21 -> 165784.32 | F21: =IFERROR(C21/E21, "TBC") -> 1.676984 | G21: =C21/E21 -> 1.676984
A22: Grand Traverse | B22: 95238 | C22: =SUMIFS(Table1[A], Table1[County], A22) +SUMIFS(Table1[B], Table1[County], A22) +SUMIFS(Table1[C], Table1[County], A22) +SUMIFS(Table1[D], Table1[County], A22) +SUMIFS(Table1[E], Table1[County], A22) +SUMIFS(Table1[F], Table1[County], A22) +SUMIFS(Table1[G], Table1[County], A22) -> 2690331 | D22: 4.86 | E22: =D22*B22 -> 462856.68 | F22: =IFERROR(C22/E22, "TBC") -> 5.8124493 | G22: =C22/E22 -> 5.8124493
A23: Gratiot | B23: 41761 | C23: =SUMIFS(Table1[A], Table1[County], A23) +SUMIFS(Table1[B], Table1[County], A23) +SUMIFS(Table1[C], Table1[County], A23) +SUMIFS(Table1[D], Table1[County], A23) +SUMIFS(Table1[E], Table1[County], A23) +SUMIFS(Table1[F], Table1[County], A23) +SUMIFS(Table1[G], Table1[County], A23) -> 206180.91 | D23: 4.86 | E23: =D23*B23 -> 202958.46 | F23: =IFERROR(C23/E23, "TBC") -> 1.0158774 | G23: =C23/E23 -> 1.0158774
A24: Iron | B24: 11631 | C24: =SUMIFS(Table1[A], Table1[County], A24) +SUMIFS(Table1[B], Table1[County], A24) +SUMIFS(Table1[C], Table1[County], A24) +SUMIFS(Table1[D], Table1[County], A24) +SUMIFS(Table1[E], Table1[County], A24) +SUMIFS(Table1[F], Table1[County], A24) +SUMIFS(Table1[G], Table1[County], A24) -> 383314 | D24: 4.86 | E24: =D24*B24 -> 56526.66 | F24: =IFERROR(C24/E24, "TBC") -> 6.7811189 | G24: =C24/E24 -> 6.7811189
A25: Kalkaska | B25: 17939 | C25: =SUMIFS(Table1[A], Table1[County], A25) +SUMIFS(Table1[B], Table1[County], A25) +SUMIFS(Table1[C], Table1[County], A25) +SUMIFS(Table1[D], Table1[County], A25) +SUMIFS(Table1[E], Table1[County], A25) +SUMIFS(Table1[F], Table1[County], A25) +SUMIFS(Table1[G], Table1[County], A25) -> 372064.86 | D25: 4.86 | E25: =D25*B25 -> 87183.54 | F25: =IFERROR(C25/E25, "TBC") -> 4.2676044 | G25: =C25/E25 -> 4.2676044
