Workbook
Name SelCounty: OFFSET('[1]County Populations'!$C$2,'[1]County Populations'!$M$6-1,0,'[1]County Populations'!$M$7-'[1]County Populations'!$M$6+1,1)

Sheet County Summary
B2: County (Population) - Threshold | D2: FEMA Inspector | E2: Emergency Work | G2: Permanent Work | L2: Total
B3: Jefferson County (84,900) - $412,614.00 | D3: Connor Blevins | E3: =SUM(Table6[[A]:[B]]) -> 239915.42 | G3: =SUM(Table6[[C]:[G]]) -> 216890 | L3: =SUM(Table6[Applicant Total]) -> 456805.42
B5: Applicant | C5: Type | D5: Status | E5: A | F5: B | G5: C | H5: D | I5: E | J5: F | K5: G | L5: Applicant Total
B6: City of Fort Atkinson | C6: City | D6: Complete | F6: 0 | I6: 0 | L6: =SUM(Table6[[#This Row],[A]:[G]]) -> 0
B7: City of Jefferson | C7: City | D7: Complete | L7: =SUM(Table6[[#This Row],[A]:[G]]) -> 0
B8: City of Lake Mills | C8: City | D8: Complete | L8: =SUM(Table6[[#This Row],[A]:[G]]) -> 0
B9: City of Waterloo | C9: City | D9: Complete | E9: 53795.63 | F9: 10235.09 | L9: =SUM(Table6[[#This Row],[A]:[G]]) -> 64030.72
B10: City of Watertown | C10: City | D10: Complete | E10: 16011.32 | F10: 5797.33 | G10: 38254.69 | H10: 0 | I10: 69860.14 | J10: 0 | K10: 0 | L10: =SUM(Table6[[#This Row],[A]:[G]]) -> 129923.48
B11: City of Whitewater | C11: City | D11: Complete | E11: 0 | F11: 0 | G11: 0 | H11: 0 | I11: 0 | L11: =SUM(Table6[[#This Row],[A]:[G]]) -> 0
B12: Jefferson Utilities | C12: County | D12: Complete | J12: 26478.61 | L12: =SUM(Table6[[#This Row],[A]:[G]]) -> 26478.61
B13: Town of Aztalan | C13: Municipality | D13: Complete | L13: =SUM(Table6[[#This Row],[A]:[G]]) -> 0
B14: Town of Cold Spring | C14: Municipality | D14: Complete | E14: 17497 | G14: 5307.53 | L14: =SUM(Table6[[#This Row],[A]:[G]]) -> 22804.53
B15: Town of Concord | C15: Municipality | D15: Complete | L15: =SUM(Table6[[#This Row],[A]:[G]]) -> 0
B16: Town of Farmington | C16: Municipality | D16: Complete | L16: =SUM(Table6[[#This Row],[A]:[G]]) -> 0
B17: Town of Hebron | C17: Municipality | D17: Complete | E17: 17872.05 | L17: =SUM(Table6[[#This Row],[A]:[G]]) -> 17872.05
B18: Village of Sullivan | C18: Municipality | D18: Complete | G18: 6099.03 | L18: =SUM(Table6[[#This Row],[A]:[G]]) -> 6099.03
B19: Village of Palmyra | C19: Municipality | D19: Complete | L19: =SUM(Table6[[#This Row],[A]:[G]]) -> 0
B20: Village of Johnson Creek | C20: Municipality | D20: Complete | L20: =SUM(Table6[[#This Row],[A]:[G]]) -> 0
B21: Village of Cambridge | C21: Municipality | D21: Complete | L21: =SUM(Table6[[#This Row],[A]:[G]]) -> 0
B22: Town of Watertown | C22: Municipality | D22: Complete | L22: =SUM(Table6[[#This Row],[A]:[G]]) -> 0
B23: Town of Waterloo | C23: Municipality | D23: Complete | E23: 8000 | L23: =SUM(Table6[[#This Row],[A]:[G]]) -> 8000
B24: Town of Sumner | C24: Municipality | D24: Complete | E24: 8000 | L24: =SUM(Table6[[#This Row],[A]:[G]]) -> 8000
B25: Town of Sullivan | C25: Municipality | D25: Complete | L25: =SUM(Table6[[#This Row],[A]:[G]]) -> 0
B26: Town of Palmyra | C26: Municipality | D26: Complete | E26: 13380 | G26: 70890 | L26: =SUM(Table6[[#This Row],[A]:[G]]) -> 84270
B27: Town of Oakland | C27: Municipality | D27: Complete | L27: =SUM(Table6[[#This Row],[A]:[G]]) -> 0
B28: Town of Milford | C28: Municipality | D28: Complete | L28: =SUM(Table6[[#This Row],[A]:[G]]) -> 0
B29: Town of Lake Mills | C29: Municipality | D29: Complete | E29: 0 | F29: 0 | G29: 0 | L29: =SUM(Table6[[#This Row],[A]:[G]]) -> 0
B30: Town of Koshkonong | C30: Municipality | D30: Complete | L30: =SUM(Table6[[#This Row],[A]:[G]]) -> 0
B31: Town of Jefferson | C31: Municipality | D31: Complete | E31: 17727 | L31: =SUM(Table6[[#This Row],[A]:[G]]) -> 17727
B32: Town of Ixonia | C32: Municipality | D32: Complete | L32: =SUM(Table6[[#This Row],[A]:[G]]) -> 0
B33: Department of Transportation | C33: Government | D33: Complete | E33: 61250 | F33: 10350 | L33: =SUM(Table6[[#This Row],[A]:[G]]) -> 71600
L34: =SUM(Table6[[#This Row],[A]:[G]]) -> 0
L35: =SUM(Table6[[#This Row],[A]:[G]]) -> 0
L36: =SUM(Table6[[#This Row],[A]:[G]]) -> 0
L37: =SUM(Table6[[#This Row],[A]:[G]]) -> 0
L38: =SUM(Table6[[#This Row],[A]:[G]]) -> 0
L39: =SUM(Table6[[#This Row],[A]:[G]]) -> 0
L40: =SUM(Table6[[#This Row],[A]:[G]]) -> 0
L41: =SUM(Table6[[#This Row],[A]:[G]]) -> 0
L42: =SUM(Table6[[#This Row],[A]:[G]]) -> 0
...

Sheet Deduction Comments
A1: Applicant | B1: Comments
A2: ='County Summary'!B6 -> City of Fort Atkinson | B2: Estimated: $0 Applicant uploaded an email indicating that there was no damage to businesses or homes and that the applicant had no overtime costs related to the event. Applicant responded to RFI and stated that they were no longer interested in participating in the PDA. Validated $0 as the applicant is not submitting costs for the PDA
A3: ='County Summary'!B7 -> City of Jefferson | B3: Estimated: $0 The documents provided for costs are for Jefferson Utilities which has already been covered. No new documents or costs have been provided. Validated: $0 as the costs provided are already covered under the Jefferson Utilities applicant
A4: ='County Summary'!B8 -> City of Lake Mills | B4: Estimated: $0 No documents uploaded, no damages. State Emergency Manager notes indicate that a call was made but the city did not return the call. Validated: $0 As the applicant did not submit costs to FEMA
A5: ='County Summary'!B9 -> City of Waterloo | B5: Cat A: Estimated: $53,795.63 Debris removal throughout the city, from roads, from powerlines. FAL, FAE. Validated: $53,795.63 utilizing applicant provided cost estimates and invoices Cat B: Estimated: $14,753.93 Emergency protective measures, search and rescue, FAL, FAE. Reduced: $2,518.84. Activities were not eligible under cat B, activity was described as weather watch and standby time for equipment. Validated: $10,235.09 utilizing applicant provided cost estimates and invoices
A6: ='County Summary'!B10 -> City of Watertown | B6: Cat A: Estimated: $16,011.32 Vegetative debris removal from streets, dam, culverts, and waterways. Debris was reduced by chipping. FAL, FAE, and Contract. Validated $16,011.32 Utilizing applicant provided estimates and invoices Cat B: Estimated: $5,797.33 Barricading facilities, sandbagging, emergency pumping. FAE, FAL, FAM. Validated $5,797.33 Utilizing applicant provided invoices Cat C: Estimated: $38,254.69 Damage to culverts, loss of road base and shoulders, loss of embankment and rip rap, loss of surface gravel and re-grade. FAL, FAE, FAM, Contract. Validated $38,254.69 Utilizing applicant provided invoices Cat D: Estimated: $288 Stream erosion of embankment near dam and culvert. FAL. Reduced: $288 below threshold for FY26 Validated $0 due to reduction Cat E: Estimated: $69,860.14 Damage to municipal airport lights and transformer, FAE, FAL, FAM, Contract. Validated $69,860.14 Utilizing applicant provided estimates and invoices Cat G: Estimated: $1,904.80 Loss of mulch and soil along walking path in park. Additional loss of rip rap along park path. Erosion and loss of material at kayak launching site and parking lot. Reduced: 1,904.80 below the threshold for FY26 Validated $0 due to reductions
A7: ='County Summary'!B11 -> City of Whitewater | B7: Estimated: $0 Documents indicate there may be cat A and cat B related costs. RFI sent on 5/11 for costs. The applicant did not respond to the RFI or provide any costs. Validated: $0 as the applicant did not provide costs or documents or respond to the RFI.
A8: ='County Summary'!B12 -> Jefferson Utilities | B8: Cat F: Estimated: $26,478.61 High winds knocked over 10 electrical poles and further compromised 2 poles. FAM, FAL, Contract (mutual aid). Validated $26,478.61 utilizing applicant provided invoices and photos.
A9: ='County Summary'!B13 -> Town of Aztalan | B9: Estimated: $0 No documents uploaded, EM notes mention they followed up with the applicant who stated they had no damages. Validated $0 due to the applicant having no damages
A10: ='County Summary'!B14 -> Town of Cold Spring | B10: Cat A: Estimated: $17,497 Vegetative debris removed from roads, ditches, and culverts. Validated: $17,497 utilizing applicant provided estimates and photos. Cat C: Estimated: $5,307.53 Piper road cuvlert picture shows undermining, applicant completed a temporary road repair but did not provide costs for a permanent fix. Validated: $5,307.53 utilizing applicant provided estimate and photos.
A11: ='County Summary'!B15 -> Town of Concord | B11: Estimated: $0 No documents uploaded, no damages. State Emergency manager notes indicated from a phone call that there were no damages Validated: $0 due to the applicant having no damages
A12: ='County Summary'!B16 -> Town of Farmington | B12: Cat A: Estimated: $2,554 Vegetative debris removed from roads, culverts, and downed power line. FAL, FAE. Reduced $2,554 below the FY26 threshold Validated: $0 due to reductions Cat C: Estimated: $2,087 Culvert undermining S Farmington rd, culvert washout on Saucer rd. FAL, FAE, FAM. Reduced: $2087 below the FY26 threshold Validated: $0 due to reductions
A13: ='County Summary'!B17 -> Town of Hebron | B13: CAT A: Estimated $17,872.05 for debris clean-up on approximately 11 roads and cemetery. Validated: $17,872.05 utilizing applicant provided photos, damage description and FAL/E cost estimates CAT B: $490.00 for storm damage documentation for emergency protection measures. Validated $0. Reduced: $490.00 for costs below the minimum threshold.
... A29: ='County Summary'!B33 -> Department of Transportation | B29: Cat A: Estimated: $61,250 for debris removal from roads due to flooding. Validated: $61,250 with applicant provided summary sheets. Cat B: Estimated: $10,350 for traffic control cost due to road closure and detours from flooding. Validated: $10,350 with applicant provided summary sheets. Cat C: Estimated: $64,000 for damages to road due to flooding. Reduced: $64,000 road is FHWA eligible. Validated: $0
A30: ='County Summary'!B34 -> 0
A31: ='County Summary'!B35 -> 0
A32: ='County Summary'!B36 -> 0
A33: ='County Summary'!B37 -> 0
A34: ='County Summary'!B38 -> 0
A35: ='County Summary'!B39 -> 0
A36: ='County Summary'!B40 -> 0
A37: ='County Summary'!B41 -> 0
A38: ='County Summary'!B42 -> 0
A39: ='County Summary'!B43 -> 0
A40: ='County Summary'!B44 -> 0
A41: ='County Summary'!B45 -> 0
... A100: ='County Summary'!B104 -> 0

Sheet Notes
A1: Created by Charles Annerino
A2: Charles.Annerino@fema.dhs.gov

Sheet County Population and Threshold
A1: Wisconsin (5,893,718) - $11,433,813
A3: County (Population) - Threshold | C3: Team Leads
A4: =D4 & " (" &F4& ")" & " - " &H4 -> Adams County (20,654) - $100,378.44 | C4: Anessa Jones | D4: Adams County | E4: 20654 | F4: 20,654 | G4: =E4*4.86 -> 100378.44 | H4: =TEXT(G4,"$#,##0.00") -> $100,378.44
A5: =D5 & " (" &F5& ")" & " - " &H5 -> Ashland County (16,027) - $77,891.22 | C5: Angel Felix | D5: Ashland County | E5: 16027 | F5: 16,027 | G5: =E5*4.86 -> 77891.22 | H5: =TEXT(G5,"$#,##0.00") -> $77,891.22
A6: =D6 & " (" &F6& ")" & " - " &H6 -> Barron County (46,711) - $227,015.46 | C6: Bassam Efein | D6: Barron County | E6: 46711 | F6: 46,711 | G6: =E6*4.86 -> 227015.46 | H6: =TEXT(G6,"$#,##0.00") -> $227,015.46
A7: =D7 & " (" &F7& ")" & " - " &H7 -> Bayfield County (16,220) - $78,829.20 | C7: Catherine Warren | D7: Bayfield County | E7: 16220 | F7: 16,220 | G7: =E7*4.86 -> 78829.2 | H7: =TEXT(G7,"$#,##0.00") -> $78,829.20
A8: =D8 & " (" &F8& ")" & " - " &H8 -> Brown County (268,740) - $1,306,076.40 | C8: Connor Blevins | D8: Brown County | E8: 268740 | F8: 268,740 | G8: =E8*4.86 -> 1306076.4 | H8: =TEXT(G8,"$#,##0.00") -> $1,306,076.40
A9: =D9 & " (" &F9& ")" & " - " &H9 -> Buffalo County (13,317) - $64,720.62 | C9: James Cathey | D9: Buffalo County | E9: 13317 | F9: 13,317 | G9: =E9*4.86 -> 64720.62 | H9: =TEXT(G9,"$#,##0.00") -> $64,720.62
A10: =D10 & " (" &F10& ")" & " - " &H10 -> Burnett County (16,526) - $80,316.36 | C10: Javon Cotton | D10: Burnett County | E10: 16526 | F10: 16,526 | G10: =E10*4.86 -> 80316.36 | H10: =TEXT(G10,"$#,##0.00") -> $80,316.36
A11: =D11 & " (" &F11& ")" & " - " &H11 -> Calumet County (52,442) - $254,868.12 | C11: Jessica Price | D11: Calumet County | E11: 52442 | F11: 52,442 | G11: =E11*4.86 -> 254868.12 | H11: =TEXT(G11,"$#,##0.00") -> $254,868.12
A12: =D12 & " (" &F12& ")" & " - " &H12 -> Chippewa County (66,297) - $322,203.42 | C12: Lindsay LaMarca | D12: Chippewa County | E12: 66297 | F12: 66,297 | G12: =E12*4.86 -> 322203.42 | H12: =TEXT(G12,"$#,##0.00") -> $322,203.42
A13: =D13 & " (" &F13& ")" & " - " &H13 -> Clark County (34,659) - $168,442.74 | C13: Maxwell Novoselac | D13: Clark County | E13: 34659 | F13: 34,659 | G13: =E13*4.86 -> 168442.74 | H13: =TEXT(G13,"$#,##0.00") -> $168,442.74
A14: =D14 & " (" &F14& ")" & " - " &H14 -> Columbia County (58,490) - $284,261.40 | C14: Natalie Schrader | D14: Columbia County | E14: 58490 | F14: 58,490 | G14: =E14*4.86 -> 284261.4 | H14: =TEXT(G14,"$#,##0.00") -> $284,261.40
A15: =D15 & " (" &F15& ")" & " - " &H15 -> Crawford County (16,113) - $78,309.18 | C15: Richard Chiarello | D15: Crawford County | E15: 16113 | F15: 16,113 | G15: =E15*4.86 -> 78309.18 | H15: =TEXT(G15,"$#,##0.00") -> $78,309.18
... A19: =D19 & " (" &F19& ")" & " - " &H19 -> Douglas County (44,295) - $215,273.70 | C19: Tracie Smith | D19: Douglas County | E19: 44295 | F19: 44,295 | G19: =E19*4.86 -> 215273.7 | H19: =TEXT(G19,"$#,##0.00") -> $215,273.70
A20: =D20 & " (" &F20& ")" & " - " &H20 -> Dunn County (45,440) - $220,838.40 | D20: Dunn County | E20: 45440 | F20: 45,440 | G20: =E20*4.86 -> 220838.4 | H20: =TEXT(G20,"$#,##0.00") -> $220,838.40
A21: =D21 & " (" &F21& ")" & " - " &H21 -> Eau Claire County (105,710) - $513,750.60 | D21: Eau Claire County | E21: 105710 | F21: 105,710 | G21: =E21*4.86 -> 513750.6 | H21: =TEXT(G21,"$#,##0.00") -> $513,750.60
A22: =D22 & " (" &F22& ")" & " - " &H22 -> Florence County (4,558) - $22,151.88 | D22: Florence County | E22: 4558 | F22: 4,558 | G22: =E22*4.86 -> 22151.88 | H22: =TEXT(G22,"$#,##0.00") -> $22,151.88
A23: =D23 & " (" &F23& ")" & " - " &H23 -> Fond Du Loc County (104,154) - $506,188.44 | D23: Fond Du Loc County | E23: 104154 | F23: 104,154 | G23: =E23*4.86 -> 506188.44 | H23: =TEXT(G23,"$#,##0.00") -> $506,188.44
A24: =D24 & " (" &F24& ")" & " - " &H24 -> Forest County (9,179) - $44,609.94 | D24: Forest County | E24: 9179 | F24: 9,179 | G24: =E24*4.86 -> 44609.94 | H24: =TEXT(G24,"$#,##0.00") -> $44,609.94
A25: =D25 & " (" &F25& ")" & " - " &H25 -> Grant County (51,938) - $252,418.68 | D25: Grant County | E25: 51938 | F25: 51,938 | G25: =E25*4.86 -> 252418.68 | H25: =TEXT(G25,"$#,##0.00") -> $252,418.68
A26: =D26 & " (" &F26& ")" & " - " &H26 -> Green County (37,093) - $180,271.98 | D26: Green County | E26: 37093 | F26: 37,093 | G26: =E26*4.86 -> 180271.98 | H26: =TEXT(G26,"$#,##0.00") -> $180,271.98
A27: =D27 & " (" &F27& ")" & " - " &H27 -> Green Lake County (19,018) - $92,427.48 | D27: Green Lake County | E27: 19018 | F27: 19,018 | G27: =E27*4.86 -> 92427.48 | H27: =TEXT(G27,"$#,##0.00") -> $92,427.48
A28: =D28 & " (" &F28& ")" & " - " &H28 -> Iowa County (23,709) - $115,225.74 | D28: Iowa County | E28: 23709 | F28: 23,709 | G28: =E28*4.86 -> 115225.74 | H28: =TEXT(G28,"$#,##0.00") -> $115,225.74
A29: =D29 & " (" &F29& ")" & " - " &H29 -> Iron County (6,137) - $29,825.82 | D29: Iron County | E29: 6137 | F29: 6,137 | G29: =E29*4.86 -> 29825.82 | H29: =TEXT(G29,"$#,##0.00") -> $29,825.82
A30: =D30 & " (" &F30& ")" & " - " &H30 -> Jackson County (21,145) - $102,764.70 | D30: Jackson County | E30: 21145 | F30: 21,145 | G30: =E30*4.86 -> 102764.7 | H30: =TEXT(G30,"$#,##0.00") -> $102,764.70
A31: =D31 & " (" &F31& ")" & " - " &H31 -> Jefferson County (84,900) - $412,614.00 | D31: Jefferson County | E31: 84900 | F31: 84,900 | G31: =E31*4.86 -> 412614 | H31: =TEXT(G31,"$#,##0.00") -> $412,614.00
... A75: =D75 & " (" &F75& ")" & " - " &H75 -> Wood County (74,207) - $360,646.02 | D75: Wood County | E75: 74207 | F75: 74,207 | G75: =E75*4.86 -> 360646.02 | H75: =TEXT(G75,"$#,##0.00") -> $360,646.02
